Workbook

Sheet Employees List
A1: Months | B1: Employee Code | C1: Name | D1: ESI Number | E1: Bank Name | F1: Account Number | G1: Total Wages 24 - 25 | H1: No of Days in a Month 2024
A2: April | B2: AC 01 | C2: BHUVANESWARAN | E2: CUB | F2: 500101011548924 | G2: 60000 | H2: 30
A3: May | B3: PR 01 | C3: VASANTHA | E3: DBS | F3: 8131010000016959 | G3: 12000 | H3: 31
A4: June | B4: PR 02 | C4: GANESH | E4: DBS | F4: 8811010012054879 | G4: 17500 | H4: 30
A5: July | B5: PR 03 | C5: ADHIKARI BALIA | E5: DBS | F5: 8131010000018948 | G5: 12000 | H5: 31
A6: August | B6: PR 04 | C6: RUPESH | E6: DBS | F6: 8131010000020156 | G6: 12000 | H6: 31
A7: September | B7: PR 05 | C7: SANJAI BHAGAT | E7: DBS | F7: 8131010000021225 | G7: 12000 | H7: 30
A8: October | B8: PR 06 | C8: ARUMUGAM | G8: 19000 | H8: 31
A9: November | B9: PR 07 | C9: AMMU | E9: IOB | F9: 65801000040238 | G9: 9500 | H9: 30
A10: December | B10: PR 08 | C10: REVATHI S | E10: DBS | F10: 8131010000016995 | G10: 9500 | H10: 31
A11: January | B11: PR 09 | C11: ABINAYA | G11: 9000 | H11: 31
A12: February | B12: PR 10 | C12: ANITHA | G12: 9000 | H12: 28
A13: March | B13: PR 11 | C13: KARTHICK | G13: 8000 | H13: 31
B14: PR 12 | C14: PINU BAGH | E14: DBS | F14: 8131010000018814 | G14: 11000
B15: PR 13 | C15: SAMSON | G15: 10500
B16: PR 14 | C16: REVATHI V | G16: 9000
B17: PR 15 | C17: BHAVANI | G17: 9000
B18: PR 16 | C18: VENKATESH | G18: 8000
B19: AC 02 | C19: SUNDARI | E19: DBS | F19: 8131010000016977 | G19: 18000
B20: AC 03 | C20: LEELA | E20: DBS | F20: 8387010000017745 | G20: 13000
B21: DR 01 | C21: Mathi | E21: DBS | F21: 8131010000016986 | G21: 20000
B22: PR 17 | C22: MUKESH | G22: 9250
B23: PR 18 | C23: NAROTTAM | G23: 11000
B24: PR 19 | C24: SIDHESHWAR | E24: DBS | F24: 8131010000018939 | G24: 10500
B25: PR 20 | C25: JAGABANDH | E25: DBS | F25: 8131010000018920 | G25: 12000
B26: PR 21 | C26: LIPAN | E26: DBS | F26: 8131010000018957 | G26: 12000
B27: PR 22 | C27: JISHU | G27: 10000
B28: PR 23 | C28: MADHAVAN | G28: 10000
B29: PR 24 | C29: NILAMANI | E29: SBI | F29: 38254473147 | G29: 11000
B30: PR 25 | C30: SAGAR | G30: 16000
B31: PR 26 | C31: CHINMAY PRADHAN | G31: 10000
B32: PR 27 | C32: PARSHU BAGH | E32: SBI | F32: 40653547928 | G32: 12000
B33: PR 28 | C33: GANESH KISAN | G33: 10000
B34: PR 29 | C34: MADAN | G34: 14000
B35: PR 30 | C35: PRAKASH | G35: 10000
B36: PR 31 | C36: AMARNGTH KISAN | G36: 11000
B37: PR 32 | C37: RANJAN BAGH | G37: 10000
B38: PR 33 | C38: SURUBABU ANGRIA | G38: 10000
B39: PR 34 | C39: PANKAJ BAGH | G39: 10000
B40: PR 35 | C40: PRINCE BADRA | G40: 10000
...

Sheet Daily Attendance Report 24-25
F1: 1 | H1: 2 | J1: 3 | L1: 4 | N1: 5 | P1: 6 | R1: 7 | T1: 8 | V1: 9 | X1: 10 | Z1: 11 | AB1: 12 | AD1: 13 | AF1: 14 | AH1: 15 | AJ1: 16 | AL1: 17 | AN1: 18 | AP1: 19 | AR1: 20 | AT1: 21 | AV1: 22 | AX1: 23 | AZ1: 24 | BB1: 25 | BD1: 26 | BF1: 27 | BH1: 28 | BJ1: 29 | BL1: 30 | BN1: 31
C2: 45352
C3: Employee Code | D3: Name | E3: Days Present / OT Hours | F3: M | G3: A | H3: M | I3: A | J3: M | K3: A | L3: M | M3: A | N3: M | O3: A | P3: M | Q3: A | R3: M | S3: A | T3: M | U3: A | V3: M | W3: A | X3: M | Y3: A | Z3: M | AA3: A | AB3: M | AC3: A | AD3: M | AE3: A | AF3: M | AG3: A | AH3: M | AI3: A | AJ3: M | AK3: A | AL3: M | AM3: A | AN3: M | AO3: A | AP3: M | AQ3: A | AR3: M | AS3: A | AT3: M | AU3: A | AV3: M | AW3: A | AX3: M | AY3: A | AZ3: M | BA3: A | BB3: M | BC3: A | BD3: M | BE3: A | BF3: M | BG3: A | BH3: M | BI3: A | BJ3: M | BK3: A | BL3: M | BM3: A | BN3: M | BO3: A
A4: =B4&D4 -> March | B4: March | D4: =IFERROR(VLOOKUP(C4,'Employees List'!$B$2:$C$28,2,0),"") | E4: =($F$4+$G$4+$H$4+$I$4+$J$4+$K$4+$L$4+$M$4+$N$4+$O$4+$P$4+$Q$4+$R$4+$S$4+$T$4+$U$4+$V$4+$W$4+$X$4+$Y$4+$Z$4+$AA$4+$AB$4+$AC$4+$AD$4+$AE$4+$AF$4+$AG$4+$AH$4+$AI$4+$AJ$4+$AK$4+$AL$4+$AM$4+$AN$4+$AO$4+$AP$4+$AQ$4+$AR$4+$AS$4+$AT$4+$AU$4+$AV$4+$AW$4+$AX$4+$AY$4+$AZ$4+$BA$4+$BB$4+$BC$4+$BD$4+$BE$4+$BF$4+$BG$4+$BH$4+$BI$4+$BJ$4+$BK$4+$BL$4+$BM$4+$BN$4+$BO$4)/2 -> 0 | F4: FALSE | G4: FALSE | H4: FALSE | I4: FALSE | J4: FALSE | K4: FALSE | L4: FALSE | M4: FALSE | N4: FALSE | O4: FALSE | P4: FALSE | Q4: FALSE | R4: FALSE | S4: FALSE | T4: FALSE | U4: FALSE | V4: FALSE | W4: FALSE | X4: FALSE | Y4: FALSE | Z4: FALSE | AA4: FALSE | AB4: FALSE | AC4: FALSE | AD4: FALSE | AE4: FALSE | AF4: FALSE | AG4: FALSE | AH4: FALSE | AI4: FALSE | AJ4: FALSE | AK4: FALSE | AL4: FALSE | AM4: FALSE | AN4: FALSE | AO4: FALSE | AP4: FALSE | AQ4: FALSE | AR4: FALSE | AS4: FALSE | AT4: FALSE | AU4: FALSE | AV4: FALSE | AW4: FALSE | AX4: FALSE | AY4: FALSE | AZ4: FALSE | BA4: FALSE | BB4: FALSE | BC4: FALSE | BD4: FALSE | BE4: FALSE | BF4: FALSE | BG4: FALSE | BH4: FALSE | BI4: FALSE | BJ4: FALSE | BK4: FALSE | BL4: FALSE | BM4: FALSE | BN4: FALSE | BO4: FALSE
A5: =A4&C5 -> MarchOT HOURS | C5: OT HOURS | E5: =SUM($F$5:$BO$5) -> 0
A6: =B6&D6 -> March | B6: March | D6: =IFERROR(VLOOKUP(C6,'Employees List'!$B$2:$C$28,2,0),"") | E6: =($F$6+$G$6+$H$6+$I$6+$J$6+$K$6+$L$6+$M$6+$N$6+$O$6+$P$6+$Q$6+$R$6+$S$6+$T$6+$U$6+$V$6+$W$6+$X$6+$Y$6+$Z$6+$AA$6+$AB$6+$AC$6+$AD$6+$AE$6+$AF$6+$AG$6+$AH$6+$AI$6+$AJ$6+$AK$6+$AL$6+$AM$6+$AN$6+$AO$6+$AP$6+$AQ$6+$AR$6+$AS$6+$AT$6+$AU$6+$AV$6+$AW$6+$AX$6+$AY$6+$AZ$6+$BA$6+$BB$6+$BC$6+$BD$6+$BE$6+$BF$6+$BG$6+$BH$6+$BI$6+$BJ$6+$BK$6+$BL$6+$BM$6+$BN$6+$BO$6)/2 -> 0 | F6: FALSE | G6: FALSE | H6: FALSE | I6: FALSE | J6: FALSE | K6: FALSE | L6: FALSE | M6: FALSE | N6: FALSE | O6: FALSE | P6: FALSE | Q6: FALSE | R6: FALSE | S6: FALSE | T6: FALSE | U6: FALSE | V6: FALSE | W6: FALSE | X6: FALSE | Y6: FALSE | Z6: FALSE | AA6: FALSE | AB6: FALSE | AC6: FALSE | AD6: FALSE | AE6: FALSE | AF6: FALSE | AG6: FALSE | AH6: FALSE | AI6: FALSE | AJ6: FALSE | AK6: FALSE | AL6: FALSE | AM6: FALSE | AN6: FALSE | AO6: FALSE | AP6: FALSE | AQ6: FALSE | AR6: FALSE | AS6: FALSE | AT6: FALSE | AU6: FALSE | AV6: FALSE | AW6: FALSE | AX6: FALSE | AY6: FALSE | AZ6: FALSE | BA6: FALSE | BB6: FALSE | BC6: FALSE | BD6: FALSE | BE6: FALSE | BF6: FALSE | BG6: FALSE | BH6: FALSE | BI6: FALSE | BJ6: FALSE | BK6: FALSE | BL6: FALSE | BM6: FALSE | BN6: FALSE | BO6: FALSE
A7: =A6&C7 -> MarchOT HOURS | C7: OT HOURS | E7: =SUM($F$7:$BO$7) -> 0
A8: =B8&D8 -> March | B8: March | D8: =IFERROR(VLOOKUP(C8,'Employees List'!$B$2:$C$28,2,0),"") | E8: =($F$8+$G$8+$H$8+$I$8+$J$8+$K$8+$L$8+$M$8+$N$8+$O$8+$P$8+$Q$8+$R$8+$S$8+$T$8+$U$8+$V$8+$W$8+$X$8+$Y$8+$Z$8+$AA$8+$AB$8+$AC$8+$AD$8+$AE$8+$AF$8+$AG$8+$AH$8+$AI$8+$AJ$8+$AK$8+$AL$8+$AM$8+$AN$8+$AO$8+$AP$8+$AQ$8+$AR$8+$AS$8+$AT$8+$AU$8+$AV$8+$AW$8+$AX$8+$AY$8+$AZ$8+$BA$8+$BB$8+$BC$8+$BD$8+$BE$8+$BF$8+$BG$8+$BH$8+$BI$8+$BJ$8+$BK$8+$BL$8+$BM$8+$BN$8+$BO$8)/2 -> 0 | F8: FALSE | G8: FALSE | H8: FALSE | I8: FALSE | J8: FALSE | K8: FALSE | L8: FALSE | M8: FALSE | N8: FALSE | O8: FALSE | P8: FALSE | Q8: FALSE | R8: FALSE | S8: FALSE | T8: FALSE | U8: FALSE | V8: FALSE | W8: FALSE | X8: FALSE | Y8: FALSE | Z8: FALSE | AA8: FALSE | AB8: FALSE | AC8: FALSE | AD8: FALSE | AE8: FALSE | AF8: FALSE | AG8: FALSE | AH8: FALSE | AI8: FALSE | AJ8: FALSE | AK8: FALSE | AL8: FALSE | AM8: FALSE | AN8: FALSE | AO8: FALSE | AP8: FALSE | AQ8: FALSE | AR8: FALSE | AS8: FALSE | AT8: FALSE | AU8: FALSE | AV8: FALSE | AW8: FALSE | AX8: FALSE | AY8: FALSE | AZ8: FALSE | BA8: FALSE | BB8: FALSE | BC8: FALSE | BD8: FALSE | BE8: FALSE | BF8: FALSE | BG8: FALSE | BH8: FALSE | BI8: FALSE | BJ8: FALSE | BK8: FALSE | BL8: FALSE | BM8: FALSE | BN8: FALSE | BO8: FALSE
A9: =A8&C9 -> MarchOT HOURS | C9: OT HOURS | E9: =SUM($F$9:$BO$9) -> 0
A10: =B10&D10 -> March | B10: March | D10: =IFERROR(VLOOKUP(C10,'Employees List'!$B$2:$C$28,2,0),"") | E10: =(F10+G10+H10+I10+J10+K10+L10+M10+N10+O10+P10+Q10+R10+S10+T10+U10+V10+W10+X10+Y10+Z10+AA10+AB10+AC10+AD10+AE10+AF10+AG10+AH10+AI10+AJ10+AK10+AL10+AM10+AN10+AO10+AP10+AQ10+AR10+AS10+AT10+AU10+AV10+AW10+AX10+AY10+AZ10+BA10+BB10+BC10+BD10+BE10+BF10+BG10+BH10+BI10+BJ10+BK10+BL10+BM10+BN10+BO10)/2 -> 0 | F10: FALSE | G10: FALSE | H10: FALSE | I10: FALSE | J10: FALSE | K10: FALSE | L10: FALSE | M10: FALSE | N10: FALSE | O10: FALSE | P10: FALSE | Q10: FALSE | R10: FALSE | S10: FALSE | T10: FALSE | U10: FALSE | V10: FALSE | W10: FALSE | X10: FALSE | Y10: FALSE | Z10: FALSE | AA10: FALSE | AB10: FALSE | AC10: FALSE | AD10: FALSE | AE10: FALSE | AF10: FALSE | AG10: FALSE | AH10: FALSE | AI10: FALSE | AJ10: FALSE | AK10: FALSE | AL10: FALSE | AM10: FALSE | AN10: FALSE | AO10: FALSE | AP10: FALSE | AQ10: FALSE | AR10: FALSE | AS10: FALSE | AT10: FALSE | AU10: FALSE | AV10: FALSE | AW10: FALSE | AX10: FALSE | AY10: FALSE | AZ10: FALSE | BA10: FALSE | BB10: FALSE | BC10: FALSE | BD10: FALSE | BE10: FALSE | BF10: FALSE | BG10: FALSE | BH10: FALSE | BI10: FALSE | BJ10: FALSE | BK10: FALSE | BL10: FALSE | BM10: FALSE | BN10: FALSE | BO10: FALSE
A11: =A10&C11 -> MarchOT HOURS | C11: OT HOURS | E11: =SUM(F11:BO11) -> 0
A12: =B12&D12 -> March | B12: March | D12: =IFERROR(VLOOKUP(C12,'Employees List'!$B$2:$C$28,2,0),"") | E12: =(F12+G12+H12+I12+J12+K12+L12+M12+N12+O12+P12+Q12+R12+S12+T12+U12+V12+W12+X12+Y12+Z12+AA12+AB12+AC12+AD12+AE12+AF12+AG12+AH12+AI12+AJ12+AK12+AL12+AM12+AN12+AO12+AP12+AQ12+AR12+AS12+AT12+AU12+AV12+AW12+AX12+AY12+AZ12+BA12+BB12+BC12+BD12+BE12+BF12+BG12+BH12+BI12+BJ12+BK12+BL12+BM12+BN12+BO12)/2 -> 0 | F12: FALSE | G12: FALSE | H12: FALSE | I12: FALSE | J12: FALSE | K12: FALSE | L12: FALSE | M12: FALSE | N12: FALSE | O12: FALSE | P12: FALSE | Q12: FALSE | R12: FALSE | S12: FALSE | T12: FALSE | U12: FALSE | V12: FALSE | W12: FALSE | X12: FALSE | Y12: FALSE | Z12: FALSE | AA12: FALSE | AB12: FALSE | AC12: FALSE | AD12: FALSE | AE12: FALSE | AF12: FALSE | AG12: FALSE | AH12: FALSE | AI12: FALSE | AJ12: FALSE | AK12: FALSE | AL12: FALSE | AM12: FALSE | AN12: FALSE | AO12: FALSE | AP12: FALSE | AQ12: FALSE | AR12: FALSE | AS12: FALSE | AT12: FALSE | AU12: FALSE | AV12: FALSE | AW12: FALSE | AX12: FALSE | AY12: FALSE | AZ12: FALSE | BA12: FALSE | BB12: FALSE | BC12: FALSE | BD12: FALSE | BE12: FALSE | BF12: FALSE | BG12: FALSE | BH12: FALSE | BI12: FALSE | BJ12: FALSE | BK12: FALSE | BL12: FALSE | BM12: FALSE | BN12: FALSE | BO12: FALSE
A13: =A12&C13 -> MarchOT HOURS | C13: OT HOURS | E13: =SUM(F13:BO13) -> 0
A14: =B14&D14 -> March | B14: March | D14: =IFERROR(VLOOKUP(C14,'Employees List'!$B$2:$C$28,2,0),"") | E14: =(F14+G14+H14+I14+J14+K14+L14+M14+N14+O14+P14+Q14+R14+S14+T14+U14+V14+W14+X14+Y14+Z14+AA14+AB14+AC14+AD14+AE14+AF14+AG14+AH14+AI14+AJ14+AK14+AL14+AM14+AN14+AO14+AP14+AQ14+AR14+AS14+AT14+AU14+AV14+AW14+AX14+AY14+AZ14+BA14+BB14+BC14+BD14+BE14+BF14+BG14+BH14+BI14+BJ14+BK14+BL14+BM14+BN14+BO14)/2 -> 0 | F14: FALSE | G14: FALSE | H14: FALSE | I14: FALSE | J14: FALSE | K14: FALSE | L14: FALSE | M14: FALSE | N14: FALSE | O14: FALSE | P14: FALSE | Q14: FALSE | R14: FALSE | S14: FALSE | T14: FALSE | U14: FALSE | V14: FALSE | W14: FALSE | X14: FALSE | Y14: FALSE | Z14: FALSE | AA14: FALSE | AB14: FALSE | AC14: FALSE | AD14: FALSE | AE14: FALSE | AF14: FALSE | AG14: FALSE | AH14: FALSE | AI14: FALSE | AJ14: FALSE | AK14: FALSE | AL14: FALSE | AM14: FALSE | AN14: FALSE | AO14: FALSE | AP14: FALSE | AQ14: FALSE | AR14: FALSE | AS14: FALSE | AT14: FALSE | AU14: FALSE | AV14: FALSE | AW14: FALSE | AX14: FALSE | AY14: FALSE | AZ14: FALSE | BA14: FALSE | BB14: FALSE | BC14: FALSE | BD14: FALSE | BE14: FALSE | BF14: FALSE | BG14: FALSE | BH14: FALSE | BI14: FALSE | BJ14: FALSE | BK14: FALSE | BL14: FALSE | BM14: FALSE | BN14: FALSE | BO14: FALSE
A15: =A14&C15 -> MarchOT HOURS | C15: OT HOURS | E15: =SUM(F15:BO15) -> 0
A16: =B16&D16 -> March | B16: March | D16: =IFERROR(VLOOKUP(C16,'Employees List'!$B$2:$C$28,2,0),"") | E16: =(F16+G16+H16+I16+J16+K16+L16+M16+N16+O16+P16+Q16+R16+S16+T16+U16+V16+W16+X16+Y16+Z16+AA16+AB16+AC16+AD16+AE16+AF16+AG16+AH16+AI16+AJ16+AK16+AL16+AM16+AN16+AO16+AP16+AQ16+AR16+AS16+AT16+AU16+AV16+AW16+AX16+AY16+AZ16+BA16+BB16+BC16+BD16+BE16+BF16+BG16+BH16+BI16+BJ16+BK16+BL16+BM16+BN16+BO16)/2 -> 0 | F16: FALSE | G16: FALSE | H16: FALSE | I16: FALSE | J16: FALSE | K16: FALSE | L16: FALSE | M16: FALSE | N16: FALSE | O16: FALSE | P16: FALSE | Q16: FALSE | R16: FALSE | S16: FALSE | T16: FALSE | U16: FALSE | V16: FALSE | W16: FALSE | X16: FALSE | Y16: FALSE | Z16: FALSE | AA16: FALSE | AB16: FALSE | AC16: FALSE | AD16: FALSE | AE16: FALSE | AF16: FALSE | AG16: FALSE | AH16: FALSE | AI16: FALSE | AJ16: FALSE | AK16: FALSE | AL16: FALSE | AM16: FALSE | AN16: FALSE | AO16: FALSE | AP16: FALSE | AQ16: FALSE | AR16: FALSE | AS16: FALSE | AT16: FALSE | AU16: FALSE | AV16: FALSE | AW16: FALSE | AX16: FALSE | AY16: FALSE | AZ16: FALSE | BA16: FALSE | BB16: FALSE | BC16: FALSE | BD16: FALSE | BE16: FALSE | BF16: FALSE | BG16: FALSE | BH16: FALSE | BI16: FALSE | BJ16: FALSE | BK16: FALSE | BL16: FALSE | BM16: FALSE | BN16: FALSE | BO16: FALSE
A17: =A16&C17 -> MarchOT HOURS | C17: OT HOURS | E17: =SUM(F17:BO17) -> 0
A18: =B18&D18 -> March | B18: March | D18: =IFERROR(VLOOKUP(C18,'Employees List'!$B$2:$C$28,2,0),"") | E18: =(F18+G18+H18+I18+J18+K18+L18+M18+N18+O18+P18+Q18+R18+S18+T18+U18+V18+W18+X18+Y18+Z18+AA18+AB18+AC18+AD18+AE18+AF18+AG18+AH18+AI18+AJ18+AK18+AL18+AM18+AN18+AO18+AP18+AQ18+AR18+AS18+AT18+AU18+AV18+AW18+AX18+AY18+AZ18+BA18+BB18+BC18+BD18+BE18+BF18+BG18+BH18+BI18+BJ18+BK18+BL18+BM18+BN18+BO18)/2 -> 0 | F18: FALSE | G18: FALSE | H18: FALSE | I18: FALSE | J18: FALSE | K18: FALSE | L18: FALSE | M18: FALSE | N18: FALSE | O18: FALSE | P18: FALSE | Q18: FALSE | R18: FALSE | S18: FALSE | T18: FALSE | U18: FALSE | V18: FALSE | W18: FALSE | X18: FALSE | Y18: FALSE | Z18: FALSE | AA18: FALSE | AB18: FALSE | AC18: FALSE | AD18: FALSE | AE18: FALSE | AF18: FALSE | AG18: FALSE | AH18: FALSE | AI18: FALSE | AJ18: FALSE | AK18: FALSE | AL18: FALSE | AM18: FALSE | AN18: FALSE | AO18: FALSE | AP18: FALSE | AQ18: FALSE | AR18: FALSE | AS18: FALSE | AT18: FALSE | AU18: FALSE | AV18: FALSE | AW18: FALSE | AX18: FALSE | AY18: FALSE | AZ18: FALSE | BA18: FALSE | BB18: FALSE | BC18: FALSE | BD18: FALSE | BE18: FALSE | BF18: FALSE | BG18: FALSE | BH18: FALSE | BI18: FALSE | BJ18: FALSE | BK18: FALSE | BL18: FALSE | BM18: FALSE | BN18: FALSE | BO18: FALSE
A19: =A18&C19 -> MarchOT HOURS | C19: OT HOURS | E19: =SUM(F19:BO19) -> 0
A20: =B20&D20 -> March | B20: March | D20: =IFERROR(VLOOKUP(C20,'Employees List'!$B$2:$C$28,2,0),"") | E20: =(F20+G20+H20+I20+J20+K20+L20+M20+N20+O20+P20+Q20+R20+S20+T20+U20+V20+W20+X20+Y20+Z20+AA20+AB20+AC20+AD20+AE20+AF20+AG20+AH20+AI20+AJ20+AK20+AL20+AM20+AN20+AO20+AP20+AQ20+AR20+AS20+AT20+AU20+AV20+AW20+AX20+AY20+AZ20+BA20+BB20+BC20+BD20+BE20+BF20+BG20+BH20+BI20+BJ20+BK20+BL20+BM20+BN20+BO20)/2 -> 0 | F20: FALSE | G20: FALSE | H20: FALSE | I20: FALSE | J20: FALSE | K20: FALSE | L20: FALSE | M20: FALSE | N20: FALSE | O20: FALSE | P20: FALSE | Q20: FALSE | R20: FALSE | S20: FALSE | T20: FALSE | U20: FALSE | V20: FALSE | W20: FALSE | X20: FALSE | Y20: FALSE | Z20: FALSE | AA20: FALSE | AB20: FALSE | AC20: FALSE | AD20: FALSE | AE20: FALSE | AF20: FALSE | AG20: FALSE | AH20: FALSE | AI20: FALSE | AJ20: FALSE | AK20: FALSE | AL20: FALSE | AM20: FALSE | AN20: FALSE | AO20: FALSE | AP20: FALSE | AQ20: FALSE | AR20: FALSE | AS20: FALSE | AT20: FALSE | AU20: FALSE | AV20: FALSE | AW20: FALSE | AX20: FALSE | AY20: FALSE | AZ20: FALSE | BA20: FALSE | BB20: FALSE | BC20: FALSE | BD20: FALSE | BE20: FALSE | BF20: FALSE | BG20: FALSE | BH20: FALSE | BI20: FALSE | BJ20: FALSE | BK20: FALSE | BL20: FALSE | BM20: FALSE | BN20: FALSE | BO20: FALSE
A21: =A20&C21 -> MarchOT HOURS | C21: OT HOURS | E21: =SUM(F21:BO21) -> 0
A22: =B22&D22 -> March | B22: March | D22: =IFERROR(VLOOKUP(C22,'Employees List'!$B$2:$C$28,2,0),"") | E22: =(F22+G22+H22+I22+J22+K22+L22+M22+N22+O22+P22+Q22+R22+S22+T22+U22+V22+W22+X22+Y22+Z22+AA22+AB22+AC22+AD22+AE22+AF22+AG22+AH22+AI22+AJ22+AK22+AL22+AM22+AN22+AO22+AP22+AQ22+AR22+AS22+AT22+AU22+AV22+AW22+AX22+AY22+AZ22+BA22+BB22+BC22+BD22+BE22+BF22+BG22+BH22+BI22+BJ22+BK22+BL22+BM22+BN22+BO22)/2 -> 0 | F22: FALSE | G22: FALSE | H22: FALSE | I22: FALSE | J22: FALSE | K22: FALSE | L22: FALSE | M22: FALSE | N22: FALSE | O22: FALSE | P22: FALSE | Q22: FALSE | R22: FALSE | S22: FALSE | T22: FALSE | U22: FALSE | V22: FALSE | W22: FALSE | X22: FALSE | Y22: FALSE | Z22: FALSE | AA22: FALSE | AB22: FALSE | AC22: FALSE | AD22: FALSE | AE22: FALSE | AF22: FALSE | AG22: FALSE | AH22: FALSE | AI22: FALSE | AJ22: FALSE | AK22: FALSE | AL22: FALSE | AM22: FALSE | AN22: FALSE | AO22: FALSE | AP22: FALSE | AQ22: FALSE | AR22: FALSE | AS22: FALSE | AT22: FALSE | AU22: FALSE | AV22: FALSE | AW22: FALSE | AX22: FALSE | AY22: FALSE | AZ22: FALSE | BA22: FALSE | BB22: FALSE | BC22: FALSE | BD22: FALSE | BE22: FALSE | BF22: FALSE | BG22: FALSE | BH22: FALSE | BI22: FALSE | BJ22: FALSE | BK22: FALSE | BL22: FALSE | BM22: FALSE | BN22: FALSE | BO22: FALSE
A23: =A22&C23 -> MarchOT HOURS | C23: OT HOURS | E23: =SUM(F23:BO23) -> 0
A24: =B24&D24 -> March | B24: March | D24: =IFERROR(VLOOKUP(C24,'Employees List'!$B$2:$C$28,2,0),"") | E24: =(F24+G24+H24+I24+J24+K24+L24+M24+N24+O24+P24+Q24+R24+S24+T24+U24+V24+W24+X24+Y24+Z24+AA24+AB24+AC24+AD24+AE24+AF24+AG24+AH24+AI24+AJ24+AK24+AL24+AM24+AN24+AO24+AP24+AQ24+AR24+AS24+AT24+AU24+AV24+AW24+AX24+AY24+AZ24+BA24+BB24+BC24+BD24+BE24+BF24+BG24+BH24+BI24+BJ24+BK24+BL24+BM24+BN24+BO24)/2 -> 0 | F24: FALSE | G24: FALSE | H24: FALSE | I24: FALSE | J24: FALSE | K24: FALSE | L24: FALSE | M24: FALSE | N24: FALSE | O24: FALSE | P24: FALSE | Q24: FALSE | R24: FALSE | S24: FALSE | T24: FALSE | U24: FALSE | V24: FALSE | W24: FALSE | X24: FALSE | Y24: FALSE | Z24: FALSE | AA24: FALSE | AB24: FALSE | AC24: FALSE | AD24: FALSE | AE24: FALSE | AF24: FALSE | AG24: FALSE | AH24: FALSE | AI24: FALSE | AJ24: FALSE | AK24: FALSE | AL24: FALSE | AM24: FALSE | AN24: FALSE | AO24: FALSE | AP24: FALSE | AQ24: FALSE | AR24: FALSE | AS24: FALSE | AT24: FALSE | AU24: FALSE | AV24: FALSE | AW24: FALSE | AX24: FALSE | AY24: FALSE | AZ24: FALSE | BA24: FALSE | BB24: FALSE | BC24: FALSE | BD24: FALSE | BE24: FALSE | BF24: FALSE | BG24: FALSE | BH24: FALSE | BI24: FALSE | BJ24: FALSE | BK24: FALSE | BL24: FALSE | BM24: FALSE | BN24: FALSE | BO24: FALSE
A25: =A24&C25 -> MarchOT HOURS | C25: OT HOURS | E25: =SUM(F25:BO25) -> 0
A26: =B26&D26 -> March | B26: March | D26: =IFERROR(VLOOKUP(C26,'Employees List'!$B$2:$C$28,2,0),"") | E26: =(F26+G26+H26+I26+J26+K26+L26+M26+N26+O26+P26+Q26+R26+S26+T26+U26+V26+W26+X26+Y26+Z26+AA26+AB26+AC26+AD26+AE26+AF26+AG26+AH26+AI26+AJ26+AK26+AL26+AM26+AN26+AO26+AP26+AQ26+AR26+AS26+AT26+AU26+AV26+AW26+AX26+AY26+AZ26+BA26+BB26+BC26+BD26+BE26+BF26+BG26+BH26+BI26+BJ26+BK26+BL26+BM26+BN26+BO26)/2 -> 0 | F26: FALSE | G26: FALSE | H26: FALSE | I26: FALSE | J26: FALSE | K26: FALSE | L26: FALSE | M26: FALSE | N26: FALSE | O26: FALSE | P26: FALSE | Q26: FALSE | R26: FALSE | S26: FALSE | T26: FALSE | U26: FALSE | V26: FALSE | W26: FALSE | X26: FALSE | Y26: FALSE | Z26: FALSE | AA26: FALSE | AB26: FALSE | AC26: FALSE | AD26: FALSE | AE26: FALSE | AF26: FALSE | AG26: FALSE | AH26: FALSE | AI26: FALSE | AJ26: FALSE | AK26: FALSE | AL26: FALSE | AM26: FALSE | AN26: FALSE | AO26: FALSE | AP26: FALSE | AQ26: FALSE | AR26: FALSE | AS26: FALSE | AT26: FALSE | AU26: FALSE | AV26: FALSE | AW26: FALSE | AX26: FALSE | AY26: FALSE | AZ26: FALSE | BA26: FALSE | BB26: FALSE | BC26: FALSE | BD26: FALSE | BE26: FALSE | BF26: FALSE | BG26: FALSE | BH26: FALSE | BI26: FALSE | BJ26: FALSE | BK26: FALSE | BL26: FALSE | BM26: FALSE | BN26: FALSE | BO26: FALSE
A27: =A26&C27 -> MarchOT HOURS | C27: OT HOURS | E27: =SUM(F27:BO27) -> 0
C28: 45383
C29: Employee Code | D29: Name | E29: Days Present / OT Hours | F29: M | G29: A | H29: M | I29: A | J29: M | K29: A | L29: M | M29: A | N29: M | O29: A | P29: M | Q29: A | R29: M | S29: A | T29: M | U29: A | V29: M | W29: A | X29: M | Y29: A | Z29: M | AA29: A | AB29: M | AC29: A | AD29: M | AE29: A | AF29: M | AG29: A | AH29: M | AI29: A | AJ29: M | AK29: A | AL29: M | AM29: A | AN29: M | AO29: A | AP29: M | AQ29: A | AR29: M | AS29: A | AT29: M | AU29: A | AV29: M | AW29: A | AX29: M | AY29: A | AZ29: M | BA29: A | BB29: M | BC29: A | BD29: M | BE29: A | BF29: M | BG29: A | BH29: M | BI29: A | BJ29: M | BK29: A | BL29: M | BM29: A | BN29: M | BO29: A
A30: =B30&D30 -> AprilBHUVANESWARAN | B30: April | C30: AC 01 | D30: =IFERROR(VLOOKUP(C30,'Employees List'!$B$2:$C$28,2,0),"") -> BHUVANESWARAN | E30: =(F30+G30+H30+I30+J30+K30+L30+M30+N30+O30+P30+Q30+R30+S30+T30+U30+V30+W30+X30+Y30+Z30+AA30+AB30+AC30+AD30+AE30+AF30+AG30+AH30+AI30+AJ30+AK30+AL30+AM30+AN30+AO30+AP30+AQ30+AR30+AS30+AT30+AU30+AV30+AW30+AX30+AY30+AZ30+BA30+BB30+BC30+BD30+BE30+BF30+BG30+BH30+BI30+BJ30+BK30+BL30+BM30+BN30+BO30)/2 -> 30 | F30: TRUE | G30: TRUE | H30: TRUE | I30: TRUE | J30: TRUE | K30: TRUE | L30: TRUE | M30: TRUE | N30: TRUE | O30: TRUE | P30: TRUE | Q30: TRUE | R30: TRUE | S30: TRUE | T30: TRUE | U30: TRUE | V30: TRUE | W30: TRUE | X30: TRUE | Y30: TRUE | Z30: TRUE | AA30: TRUE | AB30: TRUE | AC30: TRUE | AD30: TRUE | AE30: TRUE | AF30: TRUE | AG30: TRUE | AH30: TRUE | AI30: TRUE | AJ30: TRUE | AK30: TRUE | AL30: TRUE | AM30: TRUE | AN30: TRUE | AO30: TRUE | AP30: TRUE | AQ30: TRUE | AR30: TRUE | AS30: TRUE | AT30: TRUE | AU30: TRUE | AV30: TRUE | AW30: TRUE | AX30: TRUE | AY30: TRUE | AZ30: TRUE | BA30: TRUE | BB30: TRUE | BC30: TRUE | BD30: TRUE | BE30: TRUE | BF30: TRUE | BG30: TRUE | BH30: TRUE | BI30: TRUE | BJ30: TRUE | BK30: TRUE | BL30: TRUE | BM30: TRUE | BN30: FALSE | BO30: FALSE
A31: =A30&C31 -> AprilBHUVANESWARANOT HOURS | C31: OT HOURS | E31: =SUM(F31:BO31) -> 0
A32: =B32&D32 -> AprilSAGAR | B32: April | C32: PR 25 | D32: SAGAR | E32: =(F32+G32+H32+I32+J32+K32+L32+M32+N32+O32+P32+Q32+R32+S32+T32+U32+V32+W32+X32+Y32+Z32+AA32+AB32+AC32+AD32+AE32+AF32+AG32+AH32+AI32+AJ32+AK32+AL32+AM32+AN32+AO32+AP32+AQ32+AR32+AS32+AT32+AU32+AV32+AW32+AX32+AY32+AZ32+BA32+BB32+BC32+BD32+BE32+BF32+BG32+BH32+BI32+BJ32+BK32+BL32+BM32+BN32+BO32)/2 -> 11 | F32: TRUE | G32: TRUE | H32: TRUE | I32: TRUE | J32: TRUE | K32: TRUE | L32: TRUE | M32: FALSE | N32: TRUE | O32: TRUE | P32: TRUE | Q32: TRUE | R32: TRUE | S32: TRUE | T32: FALSE | U32: FALSE | V32: TRUE | W32: TRUE | X32: TRUE | Y32: TRUE | Z32: TRUE | AA32: TRUE | AB32: TRUE | AC32: TRUE | AD32: TRUE | AE32: FALSE | AF32: FALSE | AG32: FALSE | AH32: FALSE | AI32: FALSE | AJ32: FALSE | AK32: FALSE | AL32: FALSE | AM32: FALSE | AN32: FALSE | AO32: FALSE | AP32: FALSE | AQ32: FALSE | AR32: FALSE | AS32: FALSE | AT32: FALSE | AU32: FALSE | AV32: FALSE | AW32: FALSE | AX32: FALSE | AY32: FALSE | AZ32: FALSE | BA32: FALSE | BB32: FALSE | BC32: FALSE | BD32: FALSE | BE32: FALSE | BF32: FALSE | BG32: FALSE | BH32: FALSE | BI32: FALSE | BJ32: FALSE | BK32: FALSE | BL32: FALSE | BM32: FALSE | BN32: FALSE | BO32: FALSE
A33: =A32&C33 -> AprilSAGAROT HOURS | C33: OT HOURS | E33: =SUM(F33:BO33) -> 23 | F33: 2 | H33: 2 | J33: 3 | L33: 2 | N33: 1 | R33: 6 | V33: 2 | X33: 3 | Z33: 2
A34: =B34&D34 -> AprilGANESH | B34: April | C34: PR 02 | D34: =IFERROR(VLOOKUP(C34,'Employees List'!$B$2:$C$28,2,0),"") -> GANESH | E34: =(F34+G34+H34+I34+J34+K34+L34+M34+N34+O34+P34+Q34+R34+S34+T34+U34+V34+W34+X34+Y34+Z34+AA34+AB34+AC34+AD34+AE34+AF34+AG34+AH34+AI34+AJ34+AK34+AL34+AM34+AN34+AO34+AP34+AQ34+AR34+AS34+AT34+AU34+AV34+AW34+AX34+AY34+AZ34+BA34+BB34+BC34+BD34+BE34+BF34+BG34+BH34+BI34+BJ34+BK34+BL34+BM34+BN34+BO34)/2 -> 24 | F34: TRUE | G34: TRUE | H34: TRUE | I34: TRUE | J34: TRUE | K34: TRUE | L34: TRUE | M34: FALSE | N34: TRUE | O34: TRUE | P34: TRUE | Q34: TRUE | R34: TRUE | S34: TRUE | T34: TRUE | U34: TRUE | V34: TRUE | W34: FALSE | X34: FALSE | Y34: FALSE | Z34: FALSE | AA34: FALSE | AB34: TRUE | AC34: TRUE | AD34: TRUE | AE34: TRUE | AF34: TRUE | AG34: TRUE | AH34: TRUE | AI34: TRUE | AJ34: TRUE | AK34: TRUE | AL34: TRUE | AM34: TRUE | AN34: FALSE | AO34: FALSE | AP34: TRUE | AQ34: TRUE | AR34: TRUE | AS34: TRUE | AT34: TRUE | AU34: TRUE | AV34: TRUE | AW34: TRUE | AX34: FALSE | AY34: FALSE | AZ34: FALSE | BA34: FALSE | BB34: TRUE | BC34: TRUE | BD34: TRUE | BE34: TRUE | BF34: TRUE | BG34: TRUE | BH34: TRUE | BI34: TRUE | BJ34: TRUE | BK34: TRUE | BL34: TRUE | BM34: TRUE | BN34: FALSE | BO34: FALSE
A35: =A34&C35 -> AprilGANESHOT HOURS | C35: OT HOURS | E35: =SUM(F35:BO35) -> 55 | F35: 2 | H35: 2 | J35: 3 | L35: 2 | P35: 3 | R35: 8 | AB35: 2 | AD35: 2 | AF35: 1 | AH35: 2 | AR35: 3 | AV35: 4 | BB35: 3 | BD35: 4 | BF35: 2 | BH35: 8 | BJ35: 2 | BL35: 2
A36: =B36&D36 -> AprilVASANTHA | B36: April | C36: PR 01 | D36: =IFERROR(VLOOKUP(C36,'Employees List'!$B$2:$C$28,2,0),"") -> VASANTHA | E36: =(F36+G36+H36+I36+J36+K36+L36+M36+N36+O36+P36+Q36+R36+S36+T36+U36+V36+W36+X36+Y36+Z36+AA36+AB36+AC36+AD36+AE36+AF36+AG36+AH36+AI36+AJ36+AK36+AL36+AM36+AN36+AO36+AP36+AQ36+AR36+AS36+AT36+AU36+AV36+AW36+AX36+AY36+AZ36+BA36+BB36+BC36+BD36+BE36+BF36+BG36+BH36+BI36+BJ36+BK36+BL36+BM36+BN36+BO36)/2 -> 21 | F36: TRUE | G36: TRUE | H36: TRUE | I36: TRUE | J36: TRUE | K36: TRUE | L36: TRUE | M36: TRUE | N36: TRUE | O36: TRUE | P36: TRUE | Q36: TRUE | R36: TRUE | S36: TRUE | T36: TRUE | U36: TRUE | V36: TRUE | W36: TRUE | X36: TRUE | Y36: TRUE | Z36: TRUE | AA36: TRUE | AB36: TRUE | AC36: TRUE | AD36: TRUE | AE36: TRUE | AF36: FALSE | AG36: FALSE | AH36: TRUE | AI36: TRUE | AJ36: TRUE | AK36: TRUE | AL36: TRUE | AM36: TRUE | AN36: TRUE | AO36: TRUE | AP36: TRUE | AQ36: TRUE | AR36: FALSE | AS36: FALSE | AT36: FALSE | AU36: FALSE | AV36: FALSE | AW36: FALSE | AX36: FALSE | AY36: FALSE | AZ36: FALSE | BA36: FALSE | BB36: FALSE | BC36: FALSE | BD36: FALSE | BE36: FALSE | BF36: FALSE | BG36: FALSE | BH36: TRUE | BI36: TRUE | BJ36: TRUE | BK36: TRUE | BL36: TRUE | BM36: TRUE | BN36: FALSE | BO36: FALSE
C37: OT HOURS | E37: =SUM(F37:BO37) -> 33 | F37: 2 | L37: 2 | P37: 2 | R37: 5 | V37: 2 | X37: 2 | Z37: 2 | AD37: 2 | AL37: 2 | BH37: 8 | BJ37: 2 | BL37: 2
A38: =B38&D38 -> AprilSUNDARI | B38: April | C38: AC 02 | D38: =IFERROR(VLOOKUP(C38,'Employees List'!$B$2:$C$28,2,0),"") -> SUNDARI | E38: =(F38+G38+H38+I38+J38+K38+L38+M38+N38+O38+P38+Q38+R38+S38+T38+U38+V38+W38+X38+Y38+Z38+AA38+AB38+AC38+AD38+AE38+AF38+AG38+AH38+AI38+AJ38+AK38+AL38+AM38+AN38+AO38+AP38+AQ38+AR38+AS38+AT38+AU38+AV38+AW38+AX38+AY38+AZ38+BA38+BB38+BC38+BD38+BE38+BF38+BG38+BH38+BI38+BJ38+BK38+BL38+BM38+BN38+BO38)/2 -> 30 | F38: TRUE | G38: TRUE | H38: TRUE | I38: TRUE | J38: TRUE | K38: TRUE | L38: TRUE | M38: TRUE | N38: TRUE | O38: TRUE | P38: TRUE | Q38: TRUE | R38: TRUE | S38: TRUE | T38: TRUE | U38: TRUE | V38: TRUE | W38: TRUE | X38: TRUE | Y38: TRUE | Z38: TRUE | AA38: TRUE | AB38: TRUE | AC38: TRUE | AD38: TRUE | AE38: TRUE | AF38: TRUE | AG38: TRUE | AH38: TRUE | AI38: TRUE | AJ38: TRUE | AK38: TRUE | AL38: TRUE | AM38: TRUE | AN38: TRUE | AO38: TRUE | AP38: TRUE | AQ38: TRUE | AR38: TRUE | AS38: TRUE | AT38: TRUE | AU38: TRUE | AV38: TRUE | AW38: TRUE | AX38: TRUE | AY38: TRUE | AZ38: TRUE | BA38: TRUE | BB38: TRUE | BC38: TRUE | BD38: TRUE | BE38: TRUE | BF38: TRUE | BG38: TRUE | BH38: TRUE | BI38: TRUE | BJ38: TRUE | BK38: TRUE | BL38: TRUE | BM38: TRUE | BN38: FALSE | BO38: FALSE
A39: =A38&C39 -> AprilSUNDARIOT HOURS | C39: OT HOURS | E39: =SUM(F39:BO39) -> 10 | AJ39: 1 | AN39: 1 | AV39: 1 | AX39: 1 | AZ39: 1 | BB39: 1 | BD39: 1 | BF39: 1 | BL39: 2
A40: =B40&D40 -> AprilADHIKARI BALIA | B40: April | C40: PR 03 | D40: =IFERROR(VLOOKUP(C40,'Employees List'!$B$2:$C$28,2,0),"") -> ADHIKARI BALIA | E40: =(F40+G40+H40+I40+J40+K40+L40+M40+N40+O40+P40+Q40+R40+S40+T40+U40+V40+W40+X40+Y40+Z40+AA40+AB40+AC40+AD40+AE40+AF40+AG40+AH40+AI40+AJ40+AK40+AL40+AM40+AN40+AO40+AP40+AQ40+AR40+AS40+AT40+AU40+AV40+AW40+AX40+AY40+AZ40+BA40+BB40+BC40+BD40+BE40+BF40+BG40+BH40+BI40+BJ40+BK40+BL40+BM40+BN40+BO40)/2 -> 11.5 | F40: TRUE | G40: TRUE | H40: TRUE | I40: TRUE | J40: TRUE | K40: TRUE | L40: TRUE | M40: TRUE | N40: TRUE | O40: TRUE | P40: TRUE | Q40: TRUE | R40: TRUE | S40: TRUE | T40: FALSE | U40: FALSE | V40: TRUE | W40: TRUE | X40: TRUE | Y40: TRUE | Z40: TRUE | AA40: TRUE | AB40: TRUE | AC40: TRUE | AD40: TRUE | AE40: FALSE | AF40: FALSE | AG40: FALSE | AH40: FALSE | AI40: FALSE | AJ40: FALSE | AK40: FALSE | AL40: FALSE | AM40: FALSE | AN40: FALSE | AO40: FALSE | AP40: FALSE | AQ40: FALSE | AR40: FALSE | AS40: FALSE | AT40: FALSE | AU40: FALSE | AV40: FALSE | AW40: FALSE | AX40: FALSE | AY40: FALSE | AZ40: FALSE | BA40: FALSE | BB40: FALSE | BC40: FALSE | BD40: FALSE | BE40: FALSE | BF40: FALSE | BG40: FALSE | BH40: FALSE | BI40: FALSE | BJ40: FALSE | BK40: FALSE | BL40: FALSE | BM40: FALSE | BN40: FALSE | BO40: FALSE
...

Sheet Salary Calculation
A1: Salary Slip No | B1: Month | C1: Employee Code | D1: No of Days Name | E1: No of OT Name | F1: Name | G1: SALARY | H1: Date | I1: ESI Number | J1: Account Number | K1: Total Wages 24-25 | L1: Basic Pay | M1: HRA | N1: No Of Days In a Month | O1: No Of Days Present | P1: OT Hours | Q1: Bonus | R1: Advance | S1: Gross Wages | T1: OT Amount | U1: Netpay | V1: ESI | W1: Total Salary
A2: CPIEMP01 | B2: April | C2: AC 01 | D2: =B2&F2 -> AprilBHUVANESWARAN | E2: =D2&$P$1 -> AprilBHUVANESWARANOT Hours | F2: =IFERROR(VLOOKUP(C2,'Employees List'!$B$1:$G$999,2,0),"") -> BHUVANESWARAN | G2: =U2 -> 57900 | H2: 45422 | I2: =IFERROR(VLOOKUP(F2,'Employees List'!$C:$F,2,0),"") | J2: =IFERROR(VLOOKUP(C2,'Employees List'!$B$2:$G$991,5,0),"") -> 500101011548924 | K2: 57000 | L2: =K2*70% -> 39900 | M2: =K2*30% -> 17100 | N2: =IFERROR(VLOOKUP(B2,'Employees List'!$A$2:$H$991,8,0),"") -> 30 | O2: =IFERROR(VLOOKUP(D2,'Daily Attendance Report 24-25'!A1:BP999,5,0),"") -> 30 | P2: =IFERROR(VLOOKUP(E2,'Daily Attendance Report 24-25'!$A$1:$BO$617,5,0),"") -> 0 | Q2: 900 | S2: =K2/N2*O2 -> 57000 | T2: =K2/N2/8*1.5*P2 -> 0 | U2: =S2+T2-R2+Q2 -> 57900 | V2: =W2*0.75% -> 434.25 | W2: =S2+T2+Q2 -> 57900
A3: CPIEMP02 | B3: April | C3: PR 25 | D3: =B3&F3 -> AprilSAGAR | E3: =D3&$P$1 -> AprilSAGAROT Hours | F3: =IFERROR(VLOOKUP(C3,'Employees List'!$B$1:$G$999,2,0),"") -> SAGAR | G3: =U3-V3 -> 105.41667 | H3: 45422 | I3: =IFERROR(VLOOKUP(F3,'Employees List'!$C:$F,2,0),"") | J3: =IFERROR(VLOOKUP(C3,'Employees List'!$B$2:$G$991,5,0),"") | K3: =IFERROR(VLOOKUP(F3,'Employees List'!$C$1:$AB$991,5,0),"") -> 16000 | L3: =K3*70% -> 11200 | M3: =K3*30% -> 4800 | N3: =IFERROR(VLOOKUP(B3,'Employees List'!$A$2:$H$991,8,0),"") -> 30 | O3: =IFERROR(VLOOKUP(D3,'Daily Attendance Report 24-25'!A2:BP999,5,0),"") -> 11 | P3: 23 | R3: 8000 | S3: =K3/N3*O3 -> 5866.6667 | T3: =K3/N3/8*1.5*P3 -> 2300 | U3: =S3+T3-R3+Q3 -> 166.66667 | V3: =W3*0.75% -> 61.25 | W3: =S3+T3+Q3 -> 8166.6667
A4: CPIEMP03 | B4: April | C4: PR 02 | D4: =B4&F4 -> AprilGANESH | E4: =D4&$P$1 -> AprilGANESHOT Hours | F4: =IFERROR(VLOOKUP(C4,'Employees List'!$B$1:$G$999,2,0),"") -> GANESH | G4: =W4-V4-R4 -> 16812.133 | H4: 45422 | I4: =IFERROR(VLOOKUP(F4,'Employees List'!$C:$F,2,0),"") | J4: =IFERROR(VLOOKUP(C4,'Employees List'!$B$2:$G$991,5,0),"") -> 8811010012054879 | K4: =IFERROR(VLOOKUP(F4,'Employees List'!$C$1:$AB$991,5,0),"") -> 17500 | L4: =K4*70% -> 12250 | M4: =K4*30% -> 5250 | N4: =IFERROR(VLOOKUP(B4,'Employees List'!$A$2:$H$991,8,0),"") -> 30 | O4: =IFERROR(VLOOKUP(D4,'Daily Attendance Report 24-25'!A3:BP999,5,0),"") -> 24 | P4: =IFERROR(VLOOKUP(E4,'Daily Attendance Report 24-25'!$A$1:$BO$617,5,0),"") -> 55 | Q4: 450 | R4: 3500 | S4: =K4/N4*O4 -> 14000 | T4: =K4/N4/8*1.5*P4 -> 6015.625 | U4: =S4+T4-R4+Q4 -> 16965.625 | V4: =W4*0.75% -> 153.49219 | W4: =S4+T4+Q4 -> 20465.625
A5: CPIEMP04 | B5: April | C5: PR 01 | D5: =B5&F5 -> AprilVASANTHA | E5: =D5&$P$1 -> AprilVASANTHAOT Hours | F5: =IFERROR(VLOOKUP(C5,'Employees List'!$B$1:$G$999,2,0),"") -> VASANTHA | G5: =U5-V5 -> 11240.062 | H5: 45422 | I5: =IFERROR(VLOOKUP(F5,'Employees List'!$C:$F,2,0),"") | J5: =IFERROR(VLOOKUP(C5,'Employees List'!$B$2:$G$991,5,0),"") -> 8131010000016959 | K5: =IFERROR(VLOOKUP(F5,'Employees List'!$C$1:$AB$991,5,0),"") -> 12000 | L5: =K5*70% -> 8400 | M5: =K5*30% -> 3600 | N5: =IFERROR(VLOOKUP(B5,'Employees List'!$A$2:$H$991,8,0),"") -> 30 | O5: =IFERROR(VLOOKUP(D5,'Daily Attendance Report 24-25'!A4:BP999,5,0),"") -> 21 | P5: 33 | Q5: 450 | S5: =K5/N5*O5 -> 8400 | T5: =K5/N5/8*1.5*P5 -> 2475 | U5: =S5+T5-R5+Q5 -> 11325 | V5: =W5*0.75% -> 84.9375 | W5: =S5+T5+Q5 -> 11325
A6: CPIEMP05 | B6: April | C6: PR 03 | D6: =B6&F6 -> AprilADHIKARI BALIA | E6: =D6&$P$1 -> AprilADHIKARI BALIAOT Hours | F6: =IFERROR(VLOOKUP(C6,'Employees List'!$B$1:$G$999,2,0),"") -> ADHIKARI BALIA | G6: =U6-V6 -> 5183.2279 | H6: 45422 | I6: =IFERROR(VLOOKUP(F6,'Employees List'!$C:$F,2,0),"") | J6: =IFERROR(VLOOKUP(C6,'Employees List'!$B$2:$G$991,5,0),"") -> 8131010000018948 | K6: 9250 | L6: =K6*70% -> 6475 | M6: =K6*30% -> 2775 | N6: =IFERROR(VLOOKUP(B6,'Employees List'!$A$2:$H$991,8,0),"") -> 30 | O6: =IFERROR(VLOOKUP(D6,'Daily Attendance Report 24-25'!A5:BP999,5,0),"") -> 11.5 | P6: =IFERROR(VLOOKUP(E6,'Daily Attendance Report 24-25'!$A$1:$BO$617,5,0),"") -> 29 | S6: =K6/N6*O6 -> 3545.8333 | T6: =K6/N6/8*1.5*P6 -> 1676.5625 | U6: =S6+T6-R6+Q6 -> 5222.3958 | V6: =W6*0.75% -> 39.167969 | W6: =S6+T6+Q6 -> 5222.3958
A7: CPIEMP06 | B7: April | C7: AC 02 | D7: =B7&F7 -> AprilSUNDARI | E7: =D7&$P$1 -> AprilSUNDARIOT Hours | F7: =IFERROR(VLOOKUP(C7,'Employees List'!$B$1:$G$999,2,0),"") -> SUNDARI | G7: =U7-V7 -> 20172.562 | H7: 45422 | I7: =IFERROR(VLOOKUP(F7,'Employees List'!$C:$F,2,0),"") | J7: =IFERROR(VLOOKUP(C7,'Employees List'!$B$2:$G$991,5,0),"") -> 8131010000016977 | K7: =IFERROR(VLOOKUP(F7,'Employees List'!$C$1:$AB$991,5,0),"") -> 18000 | L7: =K7*70% -> 12600 | M7: =K7*30% -> 5400 | N7: =IFERROR(VLOOKUP(B7,'Employees List'!$A$2:$H$991,8,0),"") -> 30 | O7: =IFERROR(VLOOKUP(D7,'Daily Attendance Report 24-25'!A6:BP999,5,0),"") -> 30 | P7: =IFERROR(VLOOKUP(E7,'Daily Attendance Report 24-25'!$A$1:$BO$617,5,0),"") -> 10 | Q7: 1200 | S7: =K7/N7*O7 -> 18000 | T7: =K7/N7/8*1.5*P7 -> 1125 | U7: =S7+T7-R7+Q7 -> 20325 | V7: =W7*0.75% -> 152.4375 | W7: =S7+T7+Q7 -> 20325
A8: CPIEMP07 | B8: April | C8: DR 01 | D8: =B8&F8 -> AprilMathi | E8: =D8&$P$1 -> AprilMathiOT Hours | F8: =IFERROR(VLOOKUP(C8,'Employees List'!$B$1:$G$999,2,0),"") -> Mathi | G8: =U8-V8 -> 27657.667 | H8: 45422 | I8: =IFERROR(VLOOKUP(F8,'Employees List'!$C:$F,2,0),"") | J8: =IFERROR(VLOOKUP(C8,'Employees List'!$B$2:$G$991,5,0),"") -> 8131010000016986 | K8: =IFERROR(VLOOKUP(F8,'Employees List'!$C$1:$AB$991,5,0),"") -> 20000 | L8: =K8*70% -> 14000 | M8: =K8*30% -> 6000 | N8: =IFERROR(VLOOKUP(B8,'Employees List'!$A$2:$H$991,8,0),"") -> 30 | O8: =IFERROR(VLOOKUP(D8,'Daily Attendance Report 24-25'!A7:BP999,5,0),"") -> 28 | P8: =IFERROR(VLOOKUP(E8,'Daily Attendance Report 24-25'!$A$1:$BO$617,5,0),"") -> 70 | Q8: 450 | S8: =K8/N8*O8 -> 18666.667 | T8: =K8/N8/8*1.5*P8 -> 8750 | U8: =S8+T8-R8+Q8 -> 27866.667 | V8: =W8*0.75% -> 209 | W8: =S8+T8+Q8 -> 27866.667
A9: CPIEMP08 | B9: April | C9: PR 26 | D9: =B9&F9 -> AprilCHINMAY PRADHAN | E9: =D9&$P$1 -> AprilCHINMAY PRADHANOT Hours | F9: =IFERROR(VLOOKUP(C9,'Employees List'!$B$1:$G$999,2,0),"") -> CHINMAY PRADHAN | G9: =U9-V9 -> 3928.6458 | H9: 45422 | I9: =IFERROR(VLOOKUP(F9,'Employees List'!$C:$F,2,0),"") | J9: =IFERROR(VLOOKUP(C9,'Employees List'!$B$2:$G$991,5,0),"") | K9: =IFERROR(VLOOKUP(F9,'Employees List'!$C$1:$AB$991,5,0),"") -> 10000 | L9: =K9*70% -> 7000 | M9: =K9*30% -> 3000 | N9: =IFERROR(VLOOKUP(B9,'Employees List'!$A$2:$H$991,8,0),"") -> 30 | O9: =IFERROR(VLOOKUP(D9,'Daily Attendance Report 24-25'!A8:BP999,5,0),"") -> 10 | P9: =IFERROR(VLOOKUP(E9,'Daily Attendance Report 24-25'!$A$1:$BO$617,5,0),"") -> 10 | S9: =K9/N9*O9 -> 3333.3333 | T9: =K9/N9/8*1.5*P9 -> 625 | U9: =S9+T9-R9+Q9 -> 3958.3333 | V9: =W9*0.75% -> 29.6875 | W9: =S9+T9+Q9 -> 3958.3333
A10: CPIEMP09 | B10: April | C10: PR 21 | D10: =B10&F10 -> AprilLIPAN | E10: =D10&$P$1 -> AprilLIPANOT Hours | F10: =IFERROR(VLOOKUP(C10,'Employees List'!$B$1:$G$999,2,0),"") -> LIPAN | G10: =U10-V10 -> 6409.8958 | H10: 45422 | I10: =IFERROR(VLOOKUP(F10,'Employees List'!$C:$F,2,0),"") | J10: =IFERROR(VLOOKUP(C10,'Employees List'!$B$2:$G$991,5,0),"") -> 8131010000018957 | K10: 10000 | L10: =K10*70% -> 7000 | M10: =K10*30% -> 3000 | N10: =IFERROR(VLOOKUP(B10,'Employees List'!$A$2:$H$991,8,0),"") -> 30 | O10: =IFERROR(VLOOKUP(D10,'Daily Attendance Report 24-25'!A9:BP999,5,0),"") -> 11.5 | P10: 42 | S10: =K10/N10*O10 -> 3833.3333 | T10: =K10/N10/8*1.5*P10 -> 2625 | U10: =S10+T10-R10+Q10 -> 6458.3333 | V10: =W10*0.75% -> 48.4375 | W10: =S10+T10+Q10 -> 6458.3333
A11: CPIEMP10 | B11: April | C11: PR 05 | D11: =B11&F11 -> AprilSANJAI BHAGAT | E11: =D11&$P$1 -> AprilSANJAI BHAGATOT Hours | F11: =IFERROR(VLOOKUP(C11,'Employees List'!$B$1:$G$999,2,0),"") -> SANJAI BHAGAT | G11: =U11-V11 -> 6386.6341 | H11: 45422 | I11: =IFERROR(VLOOKUP(F11,'Employees List'!$C:$F,2,0),"") | J11: =IFERROR(VLOOKUP(C11,'Employees List'!$B$2:$G$991,5,0),"") -> 8131010000021225 | K11: 8750 | L11: =K11*70% -> 6125 | M11: =K11*30% -> 2625 | N11: =IFERROR(VLOOKUP(B11,'Employees List'!$A$2:$H$991,8,0),"") -> 30 | O11: =IFERROR(VLOOKUP(D11,'Daily Attendance Report 24-25'!A10:BP999,5,0),"") -> 12.5 | P11: =IFERROR(VLOOKUP(E11,'Daily Attendance Report 24-25'!$A$1:$BO$617,5,0),"") -> 51 | S11: =K11/N11*O11 -> 3645.8333 | T11: =K11/N11/8*1.5*P11 -> 2789.0625 | U11: =S11+T11-R11+Q11 -> 6434.8958 | V11: =W11*0.75% -> 48.261719 | W11: =S11+T11+Q11 -> 6434.8958
A12: CPIEMP11 | B12: May | C12: AC 01 | D12: =B12&F12 -> MayBHUVANESWARAN | E12: =D12&$P$1 -> MayBHUVANESWARANOT Hours | F12: =IFERROR(VLOOKUP(C12,'Employees List'!$B$1:$G$999,2,0),"") -> BHUVANESWARAN | G12: =U12 -> 60900 | H12: 45453 | I12: =IFERROR(VLOOKUP(F12,'Employees List'!$C:$F,2,0),"") | J12: =IFERROR(VLOOKUP(C12,'Employees List'!$B$2:$G$991,5,0),"") -> 500101011548924 | K12: =IFERROR(VLOOKUP(F12,'Employees List'!$C$1:$AB$991,5,0),"") -> 60000 | L12: =K12*70% -> 42000 | M12: =K12*30% -> 18000 | N12: =IFERROR(VLOOKUP(B12,'Employees List'!$A$2:$H$991,8,0),"") -> 31 | O12: 31 | P12: =IFERROR(VLOOKUP(E12,'Daily Attendance Report 24-25'!$A$1:$BO$617,5,0),"") -> 0 | Q12: 900 | S12: =K12/N12*O12 -> 60000 | T12: =K12/N12/8*1.5*P12 -> 0 | U12: =S12+T12-R12+Q12 -> 60900 | V12: =W12*0.75% -> 456.75 | W12: =S12+T12+Q12 -> 60900
A13: CPIEMP12 | B13: May | C13: PR 02 | D13: =B13&F13 -> MayGANESH | E13: =D13&$P$1 -> MayGANESHOT Hours | F13: =IFERROR(VLOOKUP(C13,'Employees List'!$B$1:$G$999,2,0),"") -> GANESH | G13: =U13-V13 -> 11864.14 | H13: 45453 | I13: =IFERROR(VLOOKUP(F13,'Employees List'!$C:$F,2,0),"") | J13: =IFERROR(VLOOKUP(C13,'Employees List'!$B$2:$G$991,5,0),"") -> 8811010012054879 | K13: =IFERROR(VLOOKUP(F13,'Employees List'!$C$1:$AB$991,5,0),"") -> 17500 | L13: =K13*70% -> 12250 | M13: =K13*30% -> 5250 | N13: =IFERROR(VLOOKUP(B13,'Employees List'!$A$2:$H$991,8,0),"") -> 31 | O13: =IFERROR(VLOOKUP(D13,'Daily Attendance Report 24-25'!A12:BP999,5,0),"") -> 21 | P13: =IFERROR(VLOOKUP(E13,'Daily Attendance Report 24-25'!$A$1:$BO$617,5,0),"") -> 30 | Q13: 450 | R13: 3500 | S13: =K13/N13*O13 -> 11854.839 | T13: =K13/N13/8*1.5*P13 -> 3175.4032 | U13: =S13+T13-R13+Q13 -> 11980.242 | V13: =W13*0.75% -> 116.10181 | W13: =S13+T13+Q13 -> 15480.242
A14: CPIEMP13 | B14: May | C14: PR 01 | D14: =B14&F14 -> MayVASANTHA | E14: =D14&$P$1 -> MayVASANTHAOT Hours | F14: =IFERROR(VLOOKUP(C14,'Employees List'!$B$1:$G$999,2,0),"") -> VASANTHA | G14: =U14-V14 -> 12692.794 | H14: 45453 | I14: =IFERROR(VLOOKUP(F14,'Employees List'!$C:$F,2,0),"") | J14: =IFERROR(VLOOKUP(C14,'Employees List'!$B$2:$G$991,5,0),"") -> 8131010000016959 | K14: =IFERROR(VLOOKUP(F14,'Employees List'!$C$1:$AB$991,5,0),"") -> 12000 | L14: =K14*70% -> 8400 | M14: =K14*30% -> 3600 | N14: =IFERROR(VLOOKUP(B14,'Employees List'!$A$2:$H$991,8,0),"") -> 31 | O14: 28.5 | P14: 18 | Q14: 450 | S14: =K14/N14*O14 -> 11032.258 | T14: =K14/N14/8*1.5*P14 -> 1306.4516 | U14: =S14+T14-R14+Q14 -> 12788.71 | V14: =W14*0.75% -> 95.915323 | W14: =S14+T14+Q14 -> 12788.71
A15: CPIEMP14 | B15: May | C15: AC 02 | D15: =B15&F15 -> MaySUNDARI | E15: =D15&$P$1 -> MaySUNDARIOT Hours | F15: =IFERROR(VLOOKUP(C15,'Employees List'!$B$1:$G$999,2,0),"") -> SUNDARI | G15: =U15-V15 -> 19920.435 | H15: 45453 | I15: =IFERROR(VLOOKUP(F15,'Employees List'!$C:$F,2,0),"") | J15: =IFERROR(VLOOKUP(C15,'Employees List'!$B$2:$G$991,5,0),"") -> 8131010000016977 | K15: =IFERROR(VLOOKUP(F15,'Employees List'!$C$1:$AB$991,5,0),"") -> 18000 | L15: =K15*70% -> 12600 | M15: =K15*30% -> 5400 | N15: =IFERROR(VLOOKUP(B15,'Employees List'!$A$2:$H$991,8,0),"") -> 31 | O15: =IFERROR(VLOOKUP(D15,'Daily Attendance Report 24-25'!A14:BP999,5,0),"") -> 31 | P15: 8 | Q15: 1200 | S15: =K15/N15*O15 -> 18000 | T15: =K15/N15/8*1.5*P15 -> 870.96774 | U15: =S15+T15-R15+Q15 -> 20070.968 | V15: =W15*0.75% -> 150.53226 | W15: =S15+T15+Q15 -> 20070.968
A16: CPIEMP15 | B16: May | C16: DR 01 | D16: =B16&F16 -> MayMathi | E16: =D16&$P$1 -> MayMathiOT Hours | F16: =IFERROR(VLOOKUP(C16,'Employees List'!$B$1:$G$999,2,0),"") -> Mathi | G16: =U16-V16 -> 24299.649 | H16: 45453 | I16: =IFERROR(VLOOKUP(F16,'Employees List'!$C:$F,2,0),"") | J16: =IFERROR(VLOOKUP(C16,'Employees List'!$B$2:$G$991,5,0),"") -> 8131010000016986 | K16: =IFERROR(VLOOKUP(F16,'Employees List'!$C$1:$AB$991,5,0),"") -> 20000 | L16: =K16*70% -> 14000 | M16: =K16*30% -> 6000 | N16: =IFERROR(VLOOKUP(B16,'Employees List'!$A$2:$H$991,8,0),"") -> 31 | O16: 31 | P16: 50 | Q16: 450 | R16: 2000 | S16: =K16/N16*O16 -> 20000 | T16: =K16/N16/8*1.5*P16 -> 6048.3871 | U16: =S16+T16-R16+Q16 -> 24498.387 | V16: =W16*0.75% -> 198.7379 | W16: =S16+T16+Q16 -> 26498.387
A17: CPIEMP16 | B17: May | C17: PR 03 | D17: =B17&F17 -> MayADHIKARI BALIA | E17: =D17&$P$1 -> MayADHIKARI BALIAOT Hours | F17: =IFERROR(VLOOKUP(C17,'Employees List'!$B$1:$G$999,2,0),"") -> ADHIKARI BALIA | G17: =U17-V17 -> 12812.855 | H17: 45453 | I17: =IFERROR(VLOOKUP(F17,'Employees List'!$C:$F,2,0),"") | J17: =IFERROR(VLOOKUP(C17,'Employees List'!$B$2:$G$991,5,0),"") -> 8131010000018948 | K17: =IFERROR(VLOOKUP(F17,'Employees List'!$C$1:$AB$991,5,0),"") -> 12000 | L17: =K17*70% -> 8400 | M17: =K17*30% -> 3600 | N17: =IFERROR(VLOOKUP(B17,'Employees List'!$A$2:$H$991,8,0),"") -> 31 | O17: =IFERROR(VLOOKUP(D17,'Daily Attendance Report 24-25'!A16:BP999,5,0),"") -> 18.5 | P17: 73 | Q17: 450 | S17: =K17/N17*O17 -> 7161.2903 | T17: =K17/N17/8*1.5*P17 -> 5298.3871 | U17: =S17+T17-R17+Q17 -> 12909.677 | V17: =W17*0.75% -> 96.822581 | W17: =S17+T17+Q17 -> 12909.677
A18: CPIEMP17 | B18: May | C18: PR 04 | D18: =B18&F18 -> MayRUPESH | E18: =D18&$P$1 -> MayRUPESHOT Hours | F18: =IFERROR(VLOOKUP(C18,'Employees List'!$B$1:$G$999,2,0),"") -> RUPESH | G18: =U18-V18 -> 10293.097 | H18: 45453 | I18: =IFERROR(VLOOKUP(F18,'Employees List'!$C:$F,2,0),"") | J18: =IFERROR(VLOOKUP(C18,'Employees List'!$B$2:$G$991,5,0),"") -> 8131010000020156 | K18: =IFERROR(VLOOKUP(F18,'Employees List'!$C$1:$AB$991,5,0),"") -> 12000 | L18: =K18*70% -> 8400 | M18: =K18*30% -> 3600 | N18: =IFERROR(VLOOKUP(B18,'Employees List'!$A$2:$H$991,8,0),"") -> 31 | O18: =IFERROR(VLOOKUP(D18,'Daily Attendance Report 24-25'!A17:BP999,5,0),"") -> 19 | P18: =IFERROR(VLOOKUP(E18,'Daily Attendance Report 24-25'!$A$1:$BO$617,5,0),"") -> 77 | Q18: 450 | R18: 3000 | S18: =K18/N18*O18 -> 7354.8387 | T18: =K18/N18/8*1.5*P18 -> 5588.7097 | U18: =S18+T18-R18+Q18 -> 10393.548 | V18: =W18*0.75% -> 100.45161 | W18: =S18+T18+Q18 -> 13393.548
A19: CPIEMP18 | B19: May | C19: PR 05 | D19: =B19&F19 -> MaySANJAI BHAGAT | E19: =D19&$P$1 -> MaySANJAI BHAGATOT Hours | F19: =IFERROR(VLOOKUP(C19,'Employees List'!$B$1:$G$999,2,0),"") -> SANJAI BHAGAT | G19: =U19-V19 -> 13437.169 | H19: 45453 | I19: =IFERROR(VLOOKUP(F19,'Employees List'!$C:$F,2,0),"") | J19: =IFERROR(VLOOKUP(C19,'Employees List'!$B$2:$G$991,5,0),"") -> 8131010000021225 | K19: =IFERROR(VLOOKUP(F19,'Employees List'!$C$1:$AB$991,5,0),"") -> 12000 | L19: =K19*70% -> 8400 | M19: =K19*30% -> 3600 | N19: =IFERROR(VLOOKUP(B19,'Employees List'!$A$2:$H$991,8,0),"") -> 31 | O19: =IFERROR(VLOOKUP(D19,'Daily Attendance Report 24-25'!A18:BP999,5,0),"") -> 19 | P19: =IFERROR(VLOOKUP(E19,'Daily Attendance Report 24-25'!$A$1:$BO$617,5,0),"") -> 79 | Q19: 450 | S19: =K19/N19*O19 -> 7354.8387 | T19: =K19/N19/8*1.5*P19 -> 5733.871 | U19: =S19+T19-R19+Q19 -> 13538.71 | V19: =W19*0.75% -> 101.54032 | W19: =S19+T19+Q19 -> 13538.71
A20: CPIEMP19 | B20: June | C20: AC 01 | D20: =B20&F20 -> JuneBHUVANESWARAN | E20: =D20&$P$1 -> JuneBHUVANESWARANOT Hours | F20: =IFERROR(VLOOKUP(C20,'Employees List'!$B$1:$G$999,2,0),"") -> BHUVANESWARAN | G20: =U20 -> 60900 | H20: 45453 | I20: =IFERROR(VLOOKUP(F20,'Employees List'!$C:$F,2,0),"") | J20: =IFERROR(VLOOKUP(C20,'Employees List'!$B$2:$G$991,5,0),"") -> 500101011548924 | K20: =IFERROR(VLOOKUP(F20,'Employees List'!$C$1:$AB$991,5,0),"") -> 60000 | L20: =K20*70% -> 42000 | M20: =K20*30% -> 18000 | N20: =IFERROR(VLOOKUP(B20,'Employees List'!$A$2:$H$991,8,0),"") -> 30 | O20: =IFERROR(VLOOKUP(D20,'Daily Attendance Report 24-25'!A19:BP999,5,0),"") -> 30 | P20: =IFERROR(VLOOKUP(E20,'Daily Attendance Report 24-25'!$A$1:$BO$617,5,0),"") -> 0 | Q20: 900 | S20: =K20/N20*O20 -> 60000 | T20: =K20/N20/8*1.5*P20 -> 0 | U20: =S20+T20-R20+Q20 -> 60900 | V20: =W20*0.75% -> 456.75 | W20: =S20+T20+Q20 -> 60900
A21: CPIEMP20 | B21: June | C21: PR 02 | D21: =B21&F21 -> JuneGANESH | E21: =D21&$P$1 -> JuneGANESHOT Hours | F21: =IFERROR(VLOOKUP(C21,'Employees List'!$B$1:$G$999,2,0),"") -> GANESH | G21: =U21-V21 -> 15712.742 | H21: 45453 | I21: =IFERROR(VLOOKUP(F21,'Employees List'!$C:$F,2,0),"") | J21: =IFERROR(VLOOKUP(C21,'Employees List'!$B$2:$G$991,5,0),"") -> 8811010012054879 | K21: =IFERROR(VLOOKUP(F21,'Employees List'!$C$1:$AB$991,5,0),"") -> 17500 | L21: =K21*70% -> 12250 | M21: =K21*30% -> 5250 | N21: =IFERROR(VLOOKUP(B21,'Employees List'!$A$2:$H$991,8,0),"") -> 30 | O21: =IFERROR(VLOOKUP(D21,'Daily Attendance Report 24-25'!A20:BP999,5,0),"") -> 30 | P21: =IFERROR(VLOOKUP(E21,'Daily Attendance Report 24-25'!$A$1:$BO$617,5,0),"") -> 41 | Q21: 900 | R21: 7000 | S21: =K21/N21*O21 -> 17500 | T21: =K21/N21/8*1.5*P21 -> 4484.375 | U21: =S21+T21-R21+Q21 -> 15884.375 | V21: =W21*0.75% -> 171.63281 | W21: =S21+T21+Q21 -> 22884.375
A22: CPIEMP21 | B22: June | C22: PR 01 | D22: =B22&F22 -> JuneVASANTHA | E22: =D22&$P$1 -> JuneVASANTHAOT Hours | F22: =IFERROR(VLOOKUP(C22,'Employees List'!$B$1:$G$999,2,0),"") -> VASANTHA | G22: =U22-V22 -> 14316.812 | H22: 45453 | I22: =IFERROR(VLOOKUP(F22,'Employees List'!$C:$F,2,0),"") | J22: =IFERROR(VLOOKUP(C22,'Employees List'!$B$2:$G$991,5,0),"") -> 8131010000016959 | K22: =IFERROR(VLOOKUP(F22,'Employees List'!$C$1:$AB$991,5,0),"") -> 12000 | L22: =K22*70% -> 8400 | M22: =K22*30% -> 3600 | N22: =IFERROR(VLOOKUP(B22,'Employees List'!$A$2:$H$991,8,0),"") -> 30 | O22: =IFERROR(VLOOKUP(D22,'Daily Attendance Report 24-25'!A21:BP999,5,0),"") -> 28 | P22: =IFERROR(VLOOKUP(E22,'Daily Attendance Report 24-25'!$A$1:$BO$617,5,0),"") -> 37 | Q22: 450 | S22: =K22/N22*O22 -> 11200 | T22: =K22/N22/8*1.5*P22 -> 2775 | U22: =S22+T22-R22+Q22 -> 14425 | V22: =W22*0.75% -> 108.1875 | W22: =S22+T22+Q22 -> 14425
A23: CPIEMP22 | B23: June | C23: AC 02 | D23: =B23&F23 -> JuneSUNDARI | E23: =D23&$P$1 -> JuneSUNDARIOT Hours | F23: =IFERROR(VLOOKUP(C23,'Employees List'!$B$1:$G$999,2,0),"") -> SUNDARI | G23: =U23-V23 -> 19390.969 | H23: 45483 | I23: =IFERROR(VLOOKUP(F23,'Employees List'!$C:$F,2,0),"") | J23: =IFERROR(VLOOKUP(C23,'Employees List'!$B$2:$G$991,5,0),"") -> 8131010000016977 | K23: =IFERROR(VLOOKUP(F23,'Employees List'!$C$1:$AB$991,5,0),"") -> 18000 | L23: =K23*70% -> 12600 | M23: =K23*30% -> 5400 | N23: =IFERROR(VLOOKUP(B23,'Employees List'!$A$2:$H$991,8,0),"") -> 30 | O23: =IFERROR(VLOOKUP(D23,'Daily Attendance Report 24-25'!A22:BP999,5,0),"") -> 30 | P23: =IFERROR(VLOOKUP(E23,'Daily Attendance Report 24-25'!$A$1:$BO$617,5,0),"") -> 3 | Q23: 1200 | S23: =K23/N23*O23 -> 18000 | T23: =K23/N23/8*1.5*P23 -> 337.5 | U23: =S23+T23-R23+Q23 -> 19537.5 | V23: =W23*0.75% -> 146.53125 | W23: =S23+T23+Q23 -> 19537.5
A24: CPIEMP23 | B24: June | C24: DR 01 | D24: =B24&F24 -> JuneMathi | E24: =D24&$P$1 -> JuneMathiOT Hours | F24: =IFERROR(VLOOKUP(C24,'Employees List'!$B$1:$G$999,2,0),"") -> Mathi | G24: =U24-V24 -> 23552.354 | H24: 45483 | I24: =IFERROR(VLOOKUP(F24,'Employees List'!$C:$F,2,0),"") | J24: =IFERROR(VLOOKUP(C24,'Employees List'!$B$2:$G$991,5,0),"") -> 8131010000016986 | K24: =IFERROR(VLOOKUP(F24,'Employees List'!$C$1:$AB$991,5,0),"") -> 20000 | L24: =K24*70% -> 14000 | M24: =K24*30% -> 6000 | N24: =IFERROR(VLOOKUP(B24,'Employees List'!$A$2:$H$991,8,0),"") -> 30 | O24: =IFERROR(VLOOKUP(D24,'Daily Attendance Report 24-25'!A23:BP999,5,0),"") -> 28 | P24: =IFERROR(VLOOKUP(E24,'Daily Attendance Report 24-25'!$A$1:$BO$617,5,0),"") -> 49 | Q24: 450 | R24: 1500 | S24: =K24/N24*O24 -> 18666.667 | T24: =K24/N24/8*1.5*P24 -> 6125 | U24: =S24+T24-R24+Q24 -> 23741.667 | V24: =W24*0.75% -> 189.3125 | W24: =S24+T24+Q24 -> 25241.667
A25: CPIEMP24 | B25: June | C25: PR 04 | D25: =B25&F25 -> JuneRUPESH | E25: =D25&$P$1 -> JuneRUPESHOT Hours | F25: =IFERROR(VLOOKUP(C25,'Employees List'!$B$1:$G$999,2,0),"") -> RUPESH | G25: =U25-V25 -> 21065.812 | H25: 45483 | I25: =IFERROR(VLOOKUP(F25,'Employees List'!$C:$F,2,0),"") | J25: =IFERROR(VLOOKUP(C25,'Employees List'!$B$2:$G$991,5,0),"") -> 8131010000020156 | K25: =IFERROR(VLOOKUP(F25,'Employees List'!$C$1:$AB$991,5,0),"") -> 12000 | L25: =K25*70% -> 8400 | M25: =K25*30% -> 3600 | N25: =IFERROR(VLOOKUP(B25,'Employees List'!$A$2:$H$991,8,0),"") -> 30 | O25: =IFERROR(VLOOKUP(D25,'Daily Attendance Report 24-25'!A24:BP999,5,0),"") -> 30 | P25: =IFERROR(VLOOKUP(E25,'Daily Attendance Report 24-25'!$A$1:$BO$617,5,0),"") -> 111 | Q25: 900 | S25: =K25/N25*O25 -> 12000 | T25: =K25/N25/8*1.5*P25 -> 8325 | U25: =S25+T25-R25+Q25 -> 21225 | V25: =W25*0.75% -> 159.1875 | W25: =S25+T25+Q25 -> 21225
A26: CPIEMP25 | B26: June | C26: PR 05 | D26: =B26&F26 -> JuneSANJAI BHAGAT | E26: =D26&$P$1 -> JuneSANJAI BHAGATOT Hours | F26: =IFERROR(VLOOKUP(C26,'Employees List'!$B$1:$G$999,2,0),"") -> SANJAI BHAGAT | G26: =U26-V26 -> 22480.125 | H26: 45483 | I26: =IFERROR(VLOOKUP(F26,'Employees List'!$C:$F,2,0),"") | J26: =IFERROR(VLOOKUP(C26,'Employees List'!$B$2:$G$991,5,0),"") -> 8131010000021225 | K26: =IFERROR(VLOOKUP(F26,'Employees List'!$C$1:$AB$991,5,0),"") -> 12000 | L26: =K26*70% -> 8400 | M26: =K26*30% -> 3600 | N26: =IFERROR(VLOOKUP(B26,'Employees List'!$A$2:$H$991,8,0),"") -> 30 | O26: =IFERROR(VLOOKUP(D26,'Daily Attendance Report 24-25'!A25:BP999,5,0),"") -> 30 | P26: =IFERROR(VLOOKUP(E26,'Daily Attendance Report 24-25'!$A$1:$BO$617,5,0),"") -> 130 | Q26: 900 | S26: =K26/N26*O26 -> 12000 | T26: =K26/N26/8*1.5*P26 -> 9750 | U26: =S26+T26-R26+Q26 -> 22650 | V26: =W26*0.75% -> 169.875 | W26: =S26+T26+Q26 -> 22650
A27: CPIEMP26 | B27: June | C27: PR 21 | D27: =B27&F27 -> JuneLIPAN | E27: =D27&$P$1 -> JuneLIPANOT Hours | F27: =IFERROR(VLOOKUP(C27,'Employees List'!$B$1:$G$999,2,0),"") -> LIPAN | G27: =U27-V27 -> 6476.0625 | H27: 45483 | I27: =IFERROR(VLOOKUP(F27,'Employees List'!$C:$F,2,0),"") | J27: =IFERROR(VLOOKUP(C27,'Employees List'!$B$2:$G$991,5,0),"") -> 8131010000018957 | K27: =IFERROR(VLOOKUP(F27,'Employees List'!$C$1:$AB$991,5,0),"") -> 12000 | L27: =K27*70% -> 8400 | M27: =K27*30% -> 3600 | N27: =IFERROR(VLOOKUP(B27,'Employees List'!$A$2:$H$991,8,0),"") -> 30 | O27: =IFERROR(VLOOKUP(D27,'Daily Attendance Report 24-25'!A26:BP999,5,0),"") -> 11 | P27: =IFERROR(VLOOKUP(E27,'Daily Attendance Report 24-25'!$A$1:$BO$617,5,0),"") -> 27 | Q27: 100 | S27: =K27/N27*O27 -> 4400 | T27: =K27/N27/8*1.5*P27 -> 2025 | U27: =S27+T27-R27+Q27 -> 6525 | V27: =W27*0.75% -> 48.9375 | W27: =S27+T27+Q27 -> 6525
A28: CPIEMP27 | B28: June | C28: PR 03 | D28: =B28&F28 -> JuneADHIKARI BALIA | E28: =D28&$P$1 -> JuneADHIKARI BALIAOT Hours | F28: =IFERROR(VLOOKUP(C28,'Employees List'!$B$1:$G$999,2,0),"") -> ADHIKARI BALIA | G28: =U28-V28 -> 19949.25 | H28: 45483 | I28: =IFERROR(VLOOKUP(F28,'Employees List'!$C:$F,2,0),"") | J28: =IFERROR(VLOOKUP(C28,'Employees List'!$B$2:$G$991,5,0),"") -> 8131010000018948 | K28: =IFERROR(VLOOKUP(F28,'Employees List'!$C$1:$AB$991,5,0),"") -> 12000 | L28: =K28*70% -> 8400 | M28: =K28*30% -> 3600 | N28: =IFERROR(VLOOKUP(B28,'Employees List'!$A$2:$H$991,8,0),"") -> 30 | O28: =IFERROR(VLOOKUP(D28,'Daily Attendance Report 24-25'!A27:BP999,5,0),"") -> 30 | P28: =IFERROR(VLOOKUP(E28,'Daily Attendance Report 24-25'!$A$1:$BO$617,5,0),"") -> 96 | Q28: 900 | S28: =K28/N28*O28 -> 12000 | T28: =K28/N28/8*1.5*P28 -> 7200 | U28: =S28+T28-R28+Q28 -> 20100 | V28: =W28*0.75% -> 150.75 | W28: =S28+T28+Q28 -> 20100
A29: CPIEMP28 | B29: July | C29: AC 01 | D29: =B29&F29 -> JulyBHUVANESWARAN | E29: =D29&$P$1 -> JulyBHUVANESWARANOT Hours | F29: =IFERROR(VLOOKUP(C29,'Employees List'!$B$1:$G$999,2,0),"") -> BHUVANESWARAN | G29: =U29 -> 60900 | H29: 45483 | I29: =IFERROR(VLOOKUP(F29,'Employees List'!$C:$F,2,0),"") | J29: =IFERROR(VLOOKUP(C29,'Employees List'!$B$2:$G$991,5,0),"") -> 500101011548924 | K29: =IFERROR(VLOOKUP(F29,'Employees List'!$C$1:$AB$991,5,0),"") -> 60000 | L29: =K29*70% -> 42000 | M29: =K29*30% -> 18000 | N29: =IFERROR(VLOOKUP(B29,'Employees List'!$A$2:$H$991,8,0),"") -> 31 | O29: =IFERROR(VLOOKUP(D29,'Daily Attendance Report 24-25'!A28:BP999,5,0),"") -> 31 | P29: =IFERROR(VLOOKUP(E29,'Daily Attendance Report 24-25'!$A$1:$BO$617,5,0),"") -> 0 | Q29: 900 | S29: =K29/N29*O29 -> 60000 | T29: =K29/N29/8*1.5*P29 -> 0 | U29: =S29+T29-R29+Q29 -> 60900 | V29: =W29*0.75% -> 456.75 | W29: =S29+T29+Q29 -> 60900
A30: CPIEMP29 | B30: July | C30: PR 02 | D30: =B30&F30 -> JulyGANESH | E30: =D30&$P$1 -> JulyGANESHOT Hours | F30: =IFERROR(VLOOKUP(C30,'Employees List'!$B$1:$G$999,2,0),"") -> GANESH | G30: =U30-V30 -> 12679.299 | H30: 45483 | I30: =IFERROR(VLOOKUP(F30,'Employees List'!$C:$F,2,0),"") | J30: =IFERROR(VLOOKUP(C30,'Employees List'!$B$2:$G$991,5,0),"") -> 8811010012054879 | K30: =IFERROR(VLOOKUP(F30,'Employees List'!$C$1:$AB$991,5,0),"") -> 17500 | L30: =K30*70% -> 12250 | M30: =K30*30% -> 5250 | N30: =IFERROR(VLOOKUP(B30,'Employees List'!$A$2:$H$991,8,0),"") -> 31 | O30: =IFERROR(VLOOKUP(D30,'Daily Attendance Report 24-25'!A29:BP999,5,0),"") -> 25.5 | P30: =IFERROR(VLOOKUP(E30,'Daily Attendance Report 24-25'!$A$1:$BO$617,5,0),"") -> 9 | Q30: 450 | R30: 3000 | S30: =K30/N30*O30 -> 14395.161 | T30: =K30/N30/8*1.5*P30 -> 952.62097 | U30: =S30+T30-R30+Q30 -> 12797.782 | V30: =W30*0.75% -> 118.48337 | W30: =S30+T30+Q30 -> 15797.782
A31: CPIEMP30 | B31: July | C31: PR 01 | D31: =B31&F31 -> JulyVASANTHA | E31: =D31&$P$1 -> JulyVASANTHAOT Hours | F31: =IFERROR(VLOOKUP(C31,'Employees List'!$B$1:$G$999,2,0),"") -> VASANTHA | G31: =U31-V31 -> 10627.754 | H31: 45514 | I31: =IFERROR(VLOOKUP(F31,'Employees List'!$C:$F,2,0),"") | J31: =IFERROR(VLOOKUP(C31,'Employees List'!$B$2:$G$991,5,0),"") -> 8131010000016959 | K31: =IFERROR(VLOOKUP(F31,'Employees List'!$C$1:$AB$991,5,0),"") -> 12000 | L31: =K31*70% -> 8400 | M31: =K31*30% -> 3600 | N31: =IFERROR(VLOOKUP(B31,'Employees List'!$A$2:$H$991,8,0),"") -> 31 | O31: =IFERROR(VLOOKUP(D31,'Daily Attendance Report 24-25'!A30:BP999,5,0),"") -> 26.5 | P31: =IFERROR(VLOOKUP(E31,'Daily Attendance Report 24-25'!$A$1:$BO$617,5,0),"") -> 0 | Q31: 450 | S31: =K31/N31*O31 -> 10258.065 | T31: =K31/N31/8*1.5*P31 -> 0 | U31: =S31+T31-R31+Q31 -> 10708.065 | V31: =W31*0.75% -> 80.310484 | W31: =S31+T31+Q31 -> 10708.065
A32: CPIEMP31 | B32: July | C32: AC 02 | D32: =B32&F32 -> JulySUNDARI | E32: =D32&$P$1 -> JulySUNDARIOT Hours | F32: =IFERROR(VLOOKUP(C32,'Employees List'!$B$1:$G$999,2,0),"") -> SUNDARI | G32: =U32-V32 -> 20136.544 | H32: 45514 | I32: =IFERROR(VLOOKUP(F32,'Employees List'!$C:$F,2,0),"") | J32: =IFERROR(VLOOKUP(C32,'Employees List'!$B$2:$G$991,5,0),"") -> 8131010000016977 | K32: =IFERROR(VLOOKUP(F32,'Employees List'!$C$1:$AB$991,5,0),"") -> 18000 | L32: =K32*70% -> 12600 | M32: =K32*30% -> 5400 | N32: =IFERROR(VLOOKUP(B32,'Employees List'!$A$2:$H$991,8,0),"") -> 31 | O32: =IFERROR(VLOOKUP(D32,'Daily Attendance Report 24-25'!A31:BP999,5,0),"") -> 31 | P32: =IFERROR(VLOOKUP(E32,'Daily Attendance Report 24-25'!$A$1:$BO$617,5,0),"") -> 10 | Q32: 1200 | S32: =K32/N32*O32 -> 18000 | T32: =K32/N32/8*1.5*P32 -> 1088.7097 | U32: =S32+T32-R32+Q32 -> 20288.71 | V32: =W32*0.75% -> 152.16532 | W32: =S32+T32+Q32 -> 20288.71
A33: CPIEMP32 | B33: July | C33: PR 03 | D33: =B33&F33 -> JulyADHIKARI BALIA | E33: =D33&$P$1 -> JulyADHIKARI BALIAOT Hours | F33: =IFERROR(VLOOKUP(C33,'Employees List'!$B$1:$G$999,2,0),"") -> ADHIKARI BALIA | G33: =U33-V33 -> 15214.065 | H33: 45514 | I33: =IFERROR(VLOOKUP(F33,'Employees List'!$C:$F,2,0),"") | J33: =IFERROR(VLOOKUP(C33,'Employees List'!$B$2:$G$991,5,0),"") -> 8131010000018948 | K33: =IFERROR(VLOOKUP(F33,'Employees List'!$C$1:$AB$991,5,0),"") -> 12000 | L33: =K33*70% -> 8400 | M33: =K33*30% -> 3600 | N33: =IFERROR(VLOOKUP(B33,'Employees List'!$A$2:$H$991,8,0),"") -> 31 | O33: =IFERROR(VLOOKUP(D33,'Daily Attendance Report 24-25'!A32:BP999,5,0),"") -> 30 | P33: =IFERROR(VLOOKUP(E33,'Daily Attendance Report 24-25'!$A$1:$BO$617,5,0),"") -> 45 | Q33: 450 | S33: =K33/N33*O33 -> 11612.903 | T33: =K33/N33/8*1.5*P33 -> 3266.129 | U33: =S33+T33-R33+Q33 -> 15329.032 | V33: =W33*0.75% -> 114.96774 | W33: =S33+T33+Q33 -> 15329.032
A34: CPIEMP33 | B34: July | C34: DR 01 | D34: =B34&F34 -> JulyMathi | E34: =D34&$P$1 -> JulyMathiOT Hours | F34: =IFERROR(VLOOKUP(C34,'Employees List'!$B$1:$G$999,2,0),"") -> Mathi | G34: =U34-V34 -> 22058.52 | H34: 45514 | I34: =IFERROR(VLOOKUP(F34,'Employees List'!$C:$F,2,0),"") | J34: =IFERROR(VLOOKUP(C34,'Employees List'!$B$2:$G$991,5,0),"") -> 8131010000016986 | K34: =IFERROR(VLOOKUP(F34,'Employees List'!$C$1:$AB$991,5,0),"") -> 20000 | L34: =K34*70% -> 14000 | M34: =K34*30% -> 6000 | N34: =IFERROR(VLOOKUP(B34,'Employees List'!$A$2:$H$991,8,0),"") -> 31 | O34: =IFERROR(VLOOKUP(D34,'Daily Attendance Report 24-25'!A33:BP999,5,0),"") -> 26 | P34: =IFERROR(VLOOKUP(E34,'Daily Attendance Report 24-25'!$A$1:$BO$617,5,0),"") -> 58 | Q34: 450 | R34: 2000 | S34: =K34/N34*O34 -> 16774.194 | T34: =K34/N34/8*1.5*P34 -> 7016.129 | U34: =S34+T34-R34+Q34 -> 22240.323 | V34: =W34*0.75% -> 181.80242 | W34: =S34+T34+Q34 -> 24240.323
A35: CPIEMP34 | B35: July | C35: PR 04 | D35: =B35&F35 -> JulyRUPESH | E35: =D35&$P$1 -> JulyRUPESHOT Hours | F35: =IFERROR(VLOOKUP(C35,'Employees List'!$B$1:$G$999,2,0),"") -> RUPESH | G35: =U35-V35 -> 15684.702 | H35: 45514 | I35: =IFERROR(VLOOKUP(F35,'Employees List'!$C:$F,2,0),"") | J35: =IFERROR(VLOOKUP(C35,'Employees List'!$B$2:$G$991,5,0),"") -> 8131010000020156 | K35: =IFERROR(VLOOKUP(F35,'Employees List'!$C$1:$AB$991,5,0),"") -> 12000 | L35: =K35*70% -> 8400 | M35: =K35*30% -> 3600 | N35: =IFERROR(VLOOKUP(B35,'Employees List'!$A$2:$H$991,8,0),"") -> 31 | O35: =IFERROR(VLOOKUP(D35,'Daily Attendance Report 24-25'!A34:BP999,5,0),"") -> 31 | P35: =IFERROR(VLOOKUP(E35,'Daily Attendance Report 24-25'!$A$1:$BO$617,5,0),"") -> 40 | Q35: 900 | S35: =K35/N35*O35 -> 12000 | T35: =K35/N35/8*1.5*P35 -> 2903.2258 | U35: =S35+T35-R35+Q35 -> 15803.226 | V35: =W35*0.75% -> 118.52419 | W35: =S35+T35+Q35 -> 15803.226
A36: CPIEMP35 | B36: July | C36: PR 05 | D36: =B36&F36 -> JulySANJAI BHAGAT | E36: =D36&$P$1 -> JulySANJAI BHAGATOT Hours | F36: =IFERROR(VLOOKUP(C36,'Employees List'!$B$1:$G$999,2,0),"") -> SANJAI BHAGAT | G36: =U36-V36 -> 19718.734 | H36: 45514 | I36: =IFERROR(VLOOKUP(F36,'Employees List'!$C:$F,2,0),"") | J36: =IFERROR(VLOOKUP(C36,'Employees List'!$B$2:$G$991,5,0),"") -> 8131010000021225 | K36: =IFERROR(VLOOKUP(F36,'Employees List'!$C$1:$AB$991,5,0),"") -> 12000 | L36: =K36*70% -> 8400 | M36: =K36*30% -> 3600 | N36: =IFERROR(VLOOKUP(B36,'Employees List'!$A$2:$H$991,8,0),"") -> 31 | O36: =IFERROR(VLOOKUP(D36,'Daily Attendance Report 24-25'!A35:BP999,5,0),"") -> 31 | P36: =IFERROR(VLOOKUP(E36,'Daily Attendance Report 24-25'!$A$1:$BO$617,5,0),"") -> 96 | Q36: 900 | S36: =K36/N36*O36 -> 12000 | T36: =K36/N36/8*1.5*P36 -> 6967.7419 | U36: =S36+T36-R36+Q36 -> 19867.742 | V36: =W36*0.75% -> 149.00806 | W36: =S36+T36+Q36 -> 19867.742
