Workbook

Sheet Employees List
A1: Months | B1: Employee Code | C1: Date Of Joining | D1: Date Of Rejoining | E1: Name | F1: ESI Number | G1: Bank Name | H1: Account Number | I1: Total Wages 24 - 25 | J1: Total Wages 25 - 26 | K1: No of Days in a Month 2025 | L1: Status
A2: April | B2: AC 01 | E2: BHUVANESHWARAN.V | G2: CUB | H2: 500101011548924 | I2: 60000 | J2: 66000 | K2: 30
A3: May | B3: PR 01 | E3: VASANTHA.E | G3: DBS | H3: 8131010000016959 | I3: 12000 | J3: 14500 | K3: 31
A4: June | B4: PR 02 | E4: GANESH | G4: DBS | H4: 8811010012054879 | I4: 17500 | J4: 18500 | K4: 30
A5: July | B5: PR 03 | E5: ADHIKARI BALIA.A | G5: DBS | H5: 8131010000018948 | I5: 12000 | J5: 13000 | K5: 31
A6: August | B6: PR 04 | E6: RUPESH KISAN | G6: UBI | H6: 411002010024591 | I6: 12000 | J6: 13000 | K6: 31
A7: September | B7: PR 05 | E7: SANJAY BAGARTTI.K | G7: DBS | H7: 8131010000021225 | I7: 12000 | J7: 13000 | K7: 30
A8: October | B8: PR 06 | E8: ARUMUGAM.R | G8: IB | H8: 8031517887 | I8: 19000 | J8: 21500 | K8: 31
A9: November | B9: PR 07 | E9: AMMU.S | G9: IOB | H9: 65801000040238 | I9: 9500 | J9: 10500 | K9: 30
A10: December | B10: PR 08 | E10: REVATHI.S | G10: DBS | H10: 8131010000016995 | I10: 9500 | J10: 10500 | K10: 31
A11: January | B11: PR 09 | E11: ABINAYA.V | I11: 9000 | J11: 9000 | K11: 31
A12: February | B12: PR 10 | E12: ANITHA.P | G12: IB | H12: 8054094602 | I12: 9000 | J12: 10000 | K12: 28
A13: March | B13: PR 11 | I13: 8000 | J13: 8000 | K13: 31
A14: All | B14: PR 12 | E14: PINU | G14: DBS | H14: 8131010000018814 | I14: 11000 | J14: 11000
B15: PR 13 | E15: SAMSON BODRA.P | G15: UBI | H15: 411002120007276 | I15: 10500 | J15: 11000
B16: PR 14 | E16: REVATHI.V | G16: SBI | H16: 41581902830 | I16: 9000 | J16: 10000
B17: PR 15 | E17: BHAVANI.J | G17: KVB | H17: 1616194000000849 | I17: 9000 | J17: 10000
B18: PR 16 | I18: 8000 | J18: 8000
B19: AC 02 | E19: THIRIPURA SUNDARI.R | G19: DBS | H19: 8131010000016977 | I19: 18000 | J19: 21000
B20: AC 03 | E20: LEELAVATHI.M | G20: DBS | H20: 8387010000017745 | I20: 13000 | J20: 14000
B21: DR 01 | E21: ILAMATHIVANAN.S | G21: DBS | H21: 8131010000016986 | I21: 20000 | J21: 21000
B22: PR 17 | I22: 9250 | J22: 9250
B23: PR 18 | I23: 11000 | J23: 11000
B24: PR 19 | E24: SIDHESWAR PRADHAN | G24: DBS | H24: 8131010000018939 | I24: 10500 | J24: 10500
B25: PR 20 | G25: DBS | H25: 8131010000018920 | I25: 12000 | J25: 12000
B26: PR 21 | E26: LIPAN | G26: DBS | H26: 8131010000018957 | I26: 12000 | J26: 13000
B27: PR 22 | I27: 10000 | J27: 10000
B28: PR 23 | I28: 10000 | J28: 10000
B29: PR 24 | E29: NILAMANI KISAN.B | G29: SBI | H29: 38254473147 | I29: 11000 | J29: 12000
B30: PR 25 | I30: 16000 | J30: 16000
B31: PR 26 | I31: 10000 | J31: 10000
B32: PR 27 | E32: PARSHU BAGH | G32: SBI | H32: 40653547928 | I32: 12000 | J32: 13000
B33: PR 28 | E33: GANESH KISAN.B | I33: 10000 | J33: 10000
B34: PR 29 | E34: MADHAN | I34: 14000 | J34: 14000
B35: PR 30 | E35: PRAKASH | H35: 2521711617363 | I35: 10000 | J35: 11000
B36: PR 31 | E36: RANJAN BAGH.A | H36: 411002010021257 | I36: 10000 | J36: 10000 | M36: IFSC : UBIN0541109
B37: PR 32 | E37: AMARNGTH KISAN.A | G37: IPOS | H37: 39810019872 | I37: 10000 | J37: 10000
B38: PR 33 | E38: SURUBABU ANGRIA.M | I38: 10000 | J38: 10000
B39: PR 34 | E39: PANKAJ BAGH.K | G39: SBI | H39: 34210836103 | I39: 10000 | J39: 10000
B40: PR 35 | E40: PRINCE BADRA | I40: 10000 | J40: 10000
...

Sheet Daily Attendance 25-26
F1: 1 | H1: 2 | J1: 3 | L1: 4 | N1: 5 | P1: 6 | R1: 7 | T1: 8 | V1: 9 | X1: 10 | Z1: 11 | AB1: 12 | AD1: 13 | AF1: 14 | AH1: 15 | AJ1: 16 | AL1: 17 | AN1: 18 | AP1: 19 | AR1: 20 | AT1: 21 | AV1: 22 | AX1: 23 | AZ1: 24 | BB1: 25 | BD1: 26 | BF1: 27 | BH1: 28 | BJ1: 29 | BL1: 30 | BN1: 31
C2: 45748
C3: Employee Code | D3: Name | E3: Days Present / OT Hours | F3: M | G3: A | H3: M | I3: A | J3: M | K3: A | L3: M | M3: A | N3: M | O3: A | P3: M | Q3: A | R3: M | S3: A | T3: M | U3: A | V3: M | W3: A | X3: M | Y3: A | Z3: M | AA3: A | AB3: M | AC3: A | AD3: M | AE3: A | AF3: M | AG3: A | AH3: M | AI3: A | AJ3: M | AK3: A | AL3: M | AM3: A | AN3: M | AO3: A | AP3: M | AQ3: A | AR3: M | AS3: A | AT3: M | AU3: A | AV3: M | AW3: A | AX3: M | AY3: A | AZ3: M | BA3: A | BB3: M | BC3: A | BD3: M | BE3: A | BF3: M | BG3: A | BH3: M | BI3: A | BJ3: M | BK3: A | BL3: M | BM3: A | BN3: M | BO3: A
A4: =B4&D4 -> AprilBHUVANESHWARAN.V | B4: April | C4: AC 01 | D4: =IFERROR(VLOOKUP(C4,'Employees List'!$B$2:$E1424,4,0),"") -> BHUVANESHWARAN.V | E4: =COUNTIF(F4:BO4,TRUE)/2 -> 30 | F4: TRUE | G4: TRUE | H4: TRUE | I4: TRUE | J4: TRUE | K4: TRUE | L4: TRUE | M4: TRUE | N4: TRUE | O4: TRUE | P4: TRUE | Q4: TRUE | R4: TRUE | S4: TRUE | T4: TRUE | U4: TRUE | V4: TRUE | W4: TRUE | X4: TRUE | Y4: TRUE | Z4: TRUE | AA4: TRUE | AB4: TRUE | AC4: TRUE | AD4: TRUE | AE4: TRUE | AF4: TRUE | AG4: TRUE | AH4: TRUE | AI4: TRUE | AJ4: TRUE | AK4: TRUE | AL4: TRUE | AM4: TRUE | AN4: TRUE | AO4: TRUE | AP4: TRUE | AQ4: TRUE | AR4: TRUE | AS4: TRUE | AT4: TRUE | AU4: TRUE | AV4: TRUE | AW4: TRUE | AX4: TRUE | AY4: TRUE | AZ4: TRUE | BA4: TRUE | BB4: TRUE | BC4: TRUE | BD4: TRUE | BE4: TRUE | BF4: TRUE | BG4: TRUE | BH4: TRUE | BI4: TRUE | BJ4: TRUE | BK4: TRUE | BL4: TRUE | BM4: TRUE | BN4: FALSE | BO4: FALSE
A5: =A4&C5 -> AprilBHUVANESHWARAN.VOT HOURS | C5: OT HOURS | E5: =SUM($F$5:$BO$5) -> 0
A6: =B6&D6 -> AprilTHIRIPURA SUNDARI.R | B6: April | C6: AC 02 | D6: =IFERROR(VLOOKUP(C6,'Employees List'!$B$2:$E1424,4,0),"") -> THIRIPURA SUNDARI.R | E6: =COUNTIF(F6:BO6,TRUE)/2 -> 30 | F6: TRUE | G6: TRUE | H6: TRUE | I6: TRUE | J6: TRUE | K6: TRUE | L6: TRUE | M6: TRUE | N6: TRUE | O6: TRUE | P6: TRUE | Q6: TRUE | R6: TRUE | S6: TRUE | T6: TRUE | U6: TRUE | V6: TRUE | W6: TRUE | X6: TRUE | Y6: TRUE | Z6: TRUE | AA6: TRUE | AB6: TRUE | AC6: TRUE | AD6: TRUE | AE6: TRUE | AF6: TRUE | AG6: TRUE | AH6: TRUE | AI6: TRUE | AJ6: TRUE | AK6: TRUE | AL6: TRUE | AM6: TRUE | AN6: TRUE | AO6: TRUE | AP6: TRUE | AQ6: TRUE | AR6: TRUE | AS6: TRUE | AT6: TRUE | AU6: TRUE | AV6: TRUE | AW6: TRUE | AX6: TRUE | AY6: TRUE | AZ6: TRUE | BA6: TRUE | BB6: TRUE | BC6: TRUE | BD6: TRUE | BE6: TRUE | BF6: TRUE | BG6: TRUE | BH6: TRUE | BI6: TRUE | BJ6: TRUE | BK6: TRUE | BL6: TRUE | BM6: TRUE | BN6: FALSE | BO6: FALSE
A7: =A6&C7 -> AprilTHIRIPURA SUNDARI.ROT HOURS | C7: OT HOURS | E7: =SUM($F$7:$BO$7) -> 8 | J7: 1 | X7: 1 | AJ7: 1 | AL7: 1 | AP7: 1 | AZ7: 1 | BB7: 1 | BH7: 1
A8: =B8&D8 -> AprilGANESH | B8: April | C8: PR 02 | D8: =IFERROR(VLOOKUP(C8,'Employees List'!$B$2:$E1424,4,0),"") -> GANESH | E8: =COUNTIF(F8:BO8,TRUE)/2 -> 22 | F8: TRUE | G8: TRUE | H8: FALSE | I8: FALSE | J8: FALSE | K8: FALSE | L8: TRUE | M8: TRUE | N8: TRUE | O8: TRUE | P8: TRUE | Q8: TRUE | R8: TRUE | S8: TRUE | T8: TRUE | U8: TRUE | V8: TRUE | W8: TRUE | X8: FALSE | Y8: FALSE | Z8: FALSE | AA8: FALSE | AB8: FALSE | AC8: FALSE | AD8: FALSE | AE8: FALSE | AF8: FALSE | AG8: FALSE | AH8: FALSE | AI8: FALSE | AJ8: TRUE | AK8: TRUE | AL8: TRUE | AM8: TRUE | AN8: TRUE | AO8: TRUE | AP8: TRUE | AQ8: TRUE | AR8: TRUE | AS8: TRUE | AT8: TRUE | AU8: TRUE | AV8: TRUE | AW8: TRUE | AX8: TRUE | AY8: TRUE | AZ8: TRUE | BA8: TRUE | BB8: TRUE | BC8: TRUE | BD8: TRUE | BE8: TRUE | BF8: TRUE | BG8: TRUE | BH8: TRUE | BI8: TRUE | BJ8: TRUE | BK8: TRUE | BL8: TRUE | BM8: TRUE | BN8: FALSE | BO8: FALSE
A9: =A8&C9 -> AprilGANESHOT HOURS | C9: OT HOURS | E9: =SUM($F$9:$BO$9) -> 22 | N9: 2 | AJ9: 2 | AL9: 2 | AN9: 3 | AP9: 3 | AR9: 2 | AT9: 3 | AZ9: 2 | BJ9: 3
A10: =B10&D10 -> AprilILAMATHIVANAN.S | B10: April | C10: DR 01 | D10: =IFERROR(VLOOKUP(C10,'Employees List'!$B$2:$E1424,4,0),"") -> ILAMATHIVANAN.S | E10: =COUNTIF(F10:BO10,TRUE)/2 -> 23 | F10: TRUE | G10: TRUE | H10: TRUE | I10: TRUE | J10: TRUE | K10: TRUE | L10: TRUE | M10: TRUE | N10: TRUE | O10: TRUE | P10: TRUE | Q10: TRUE | R10: FALSE | S10: FALSE | T10: TRUE | U10: TRUE | V10: TRUE | W10: TRUE | X10: TRUE | Y10: TRUE | Z10: FALSE | AA10: FALSE | AB10: FALSE | AC10: FALSE | AD10: FALSE | AE10: FALSE | AF10: FALSE | AG10: FALSE | AH10: FALSE | AI10: FALSE | AJ10: TRUE | AK10: TRUE | AL10: TRUE | AM10: TRUE | AN10: TRUE | AO10: TRUE | AP10: TRUE | AQ10: TRUE | AR10: TRUE | AS10: TRUE | AT10: FALSE | AU10: FALSE | AV10: TRUE | AW10: TRUE | AX10: TRUE | AY10: TRUE | AZ10: TRUE | BA10: TRUE | BB10: TRUE | BC10: TRUE | BD10: TRUE | BE10: TRUE | BF10: TRUE | BG10: TRUE | BH10: TRUE | BI10: TRUE | BJ10: TRUE | BK10: TRUE | BL10: TRUE | BM10: TRUE | BN10: FALSE | BO10: FALSE
A11: =A10&C11 -> AprilILAMATHIVANAN.SOT HOURS | C11: OT HOURS | E11: =SUM(F11:BO11) -> 41 | F11: 1 | H11: 2 | N11: 2 | T11: 1 | V11: 3 | AJ11: 4 | AL11: 4 | AN11: 1 | AP11: 4 | AV11: 5 | AX11: 1 | AZ11: 3 | BD11: 2 | BH11: 1 | BJ11: 5 | BL11: 2
A12: =B12&D12 -> AprilAMMU.S | B12: April | C12: PR 07 | D12: =IFERROR(VLOOKUP(C12,'Employees List'!$B$2:$E1424,4,0),"") -> AMMU.S | E12: =COUNTIF(F12:BO12,TRUE)/2 -> 30 | F12: TRUE | G12: TRUE | H12: TRUE | I12: TRUE | J12: TRUE | K12: TRUE | L12: TRUE | M12: TRUE | N12: TRUE | O12: TRUE | P12: TRUE | Q12: TRUE | R12: TRUE | S12: TRUE | T12: TRUE | U12: TRUE | V12: TRUE | W12: TRUE | X12: TRUE | Y12: TRUE | Z12: TRUE | AA12: TRUE | AB12: TRUE | AC12: TRUE | AD12: TRUE | AE12: TRUE | AF12: TRUE | AG12: TRUE | AH12: TRUE | AI12: TRUE | AJ12: TRUE | AK12: TRUE | AL12: TRUE | AM12: TRUE | AN12: TRUE | AO12: TRUE | AP12: TRUE | AQ12: TRUE | AR12: TRUE | AS12: TRUE | AT12: TRUE | AU12: TRUE | AV12: TRUE | AW12: TRUE | AX12: TRUE | AY12: TRUE | AZ12: TRUE | BA12: TRUE | BB12: TRUE | BC12: TRUE | BD12: TRUE | BE12: TRUE | BF12: TRUE | BG12: TRUE | BH12: TRUE | BI12: TRUE | BJ12: TRUE | BK12: TRUE | BL12: TRUE | BM12: TRUE | BN12: FALSE | BO12: FALSE
A13: =A12&C13 -> AprilAMMU.SOT HOURS | C13: OT HOURS | E13: =SUM(F13:BO13) -> 11 | AJ13: 2 | AL13: 1 | AP13: 2 | AT13: 2 | AV13: 2 | BJ13: 2
A14: =B14&D14 -> AprilREVATHI.S | B14: April | C14: PR 08 | D14: =IFERROR(VLOOKUP(C14,'Employees List'!$B$2:$E1424,4,0),"") -> REVATHI.S | E14: =COUNTIF(F14:BO14,TRUE)/2 -> 29 | F14: FALSE | G14: FALSE | H14: TRUE | I14: TRUE | J14: TRUE | K14: TRUE | L14: TRUE | M14: TRUE | N14: TRUE | O14: TRUE | P14: TRUE | Q14: TRUE | R14: TRUE | S14: TRUE | T14: TRUE | U14: TRUE | V14: TRUE | W14: TRUE | X14: TRUE | Y14: TRUE | Z14: TRUE | AA14: TRUE | AB14: TRUE | AC14: TRUE | AD14: TRUE | AE14: TRUE | AF14: TRUE | AG14: TRUE | AH14: TRUE | AI14: TRUE | AJ14: TRUE | AK14: TRUE | AL14: TRUE | AM14: TRUE | AN14: TRUE | AO14: TRUE | AP14: TRUE | AQ14: TRUE | AR14: TRUE | AS14: TRUE | AT14: TRUE | AU14: TRUE | AV14: TRUE | AW14: TRUE | AX14: TRUE | AY14: TRUE | AZ14: TRUE | BA14: TRUE | BB14: TRUE | BC14: TRUE | BD14: TRUE | BE14: TRUE | BF14: TRUE | BG14: TRUE | BH14: TRUE | BI14: TRUE | BJ14: TRUE | BK14: TRUE | BL14: TRUE | BM14: TRUE | BN14: FALSE | BO14: FALSE
A15: =A14&C15 -> AprilREVATHI.SOT HOURS | C15: OT HOURS | E15: =SUM(F15:BO15) -> 9 | AJ15: 2 | AL15: 1 | AP15: 2 | AV15: 2 | BJ15: 2
A16: =B16&D16 -> AprilLEELAVATHI.M | B16: April | C16: AC 03 | D16: =IFERROR(VLOOKUP(C16,'Employees List'!$B$2:$E1424,4,0),"") -> LEELAVATHI.M | E16: =COUNTIF(F16:BO16,TRUE)/2 -> 30 | F16: TRUE | G16: TRUE | H16: TRUE | I16: TRUE | J16: TRUE | K16: TRUE | L16: TRUE | M16: TRUE | N16: TRUE | O16: TRUE | P16: TRUE | Q16: TRUE | R16: TRUE | S16: TRUE | T16: TRUE | U16: TRUE | V16: TRUE | W16: TRUE | X16: TRUE | Y16: TRUE | Z16: TRUE | AA16: TRUE | AB16: TRUE | AC16: TRUE | AD16: TRUE | AE16: TRUE | AF16: TRUE | AG16: TRUE | AH16: TRUE | AI16: TRUE | AJ16: TRUE | AK16: TRUE | AL16: TRUE | AM16: TRUE | AN16: TRUE | AO16: TRUE | AP16: TRUE | AQ16: TRUE | AR16: TRUE | AS16: TRUE | AT16: TRUE | AU16: TRUE | AV16: TRUE | AW16: TRUE | AX16: TRUE | AY16: TRUE | AZ16: TRUE | BA16: TRUE | BB16: TRUE | BC16: TRUE | BD16: TRUE | BE16: TRUE | BF16: TRUE | BG16: TRUE | BH16: TRUE | BI16: TRUE | BJ16: TRUE | BK16: TRUE | BL16: TRUE | BM16: TRUE | BN16: FALSE | BO16: FALSE
A17: =A16&C17 -> AprilLEELAVATHI.MOT HOURS | C17: OT HOURS | E17: =SUM(F17:BO17) -> 3 | AJ17: 1 | AL17: 1 | AT17: 1
A18: =B18&D18 -> AprilPARSHU BAGH | B18: April | C18: PR 27 | D18: =IFERROR(VLOOKUP(C18,'Employees List'!$B$2:$E1424,4,0),"") -> PARSHU BAGH | E18: =COUNTIF(F18:BO18,TRUE)/2 -> 9 | F18: TRUE | G18: TRUE | H18: TRUE | I18: TRUE | J18: TRUE | K18: TRUE | L18: TRUE | M18: TRUE | N18: TRUE | O18: TRUE | P18: TRUE | Q18: TRUE | R18: TRUE | S18: TRUE | T18: TRUE | U18: TRUE | V18: TRUE | W18: TRUE | X18: FALSE | Y18: FALSE | Z18: FALSE | AA18: FALSE | AB18: FALSE | AC18: FALSE | AD18: FALSE | AE18: FALSE | AF18: FALSE | AG18: FALSE | AH18: FALSE | AI18: FALSE | AJ18: FALSE | AK18: FALSE | AL18: FALSE | AM18: FALSE | AN18: FALSE | AO18: FALSE | AP18: FALSE | AQ18: FALSE | AR18: FALSE | AS18: FALSE | AT18: FALSE | AU18: FALSE | AV18: FALSE | AW18: FALSE | AX18: FALSE | AY18: FALSE | AZ18: FALSE | BA18: FALSE | BB18: FALSE | BC18: FALSE | BD18: FALSE | BE18: FALSE | BF18: FALSE | BG18: FALSE | BH18: FALSE | BI18: FALSE | BJ18: FALSE | BK18: FALSE | BL18: FALSE | BM18: FALSE | BN18: FALSE | BO18: FALSE
A19: =A18&C19 -> AprilPARSHU BAGHOT HOURS | C19: OT HOURS | E19: =SUM(F19:BO19) -> 2 | N19: 2
A20: =B20&D20 -> AprilPINU | B20: April | C20: PR 12 | D20: =IFERROR(VLOOKUP(C20,'Employees List'!$B$2:$E1424,4,0),"") -> PINU | E20: =COUNTIF(F20:BO20,TRUE)/2 -> 9 | F20: TRUE | G20: TRUE | H20: TRUE | I20: TRUE | J20: TRUE | K20: TRUE | L20: TRUE | M20: TRUE | N20: TRUE | O20: TRUE | P20: TRUE | Q20: TRUE | R20: TRUE | S20: TRUE | T20: TRUE | U20: TRUE | V20: TRUE | W20: TRUE | X20: FALSE | Y20: FALSE | Z20: FALSE | AA20: FALSE | AB20: FALSE | AC20: FALSE | AD20: FALSE | AE20: FALSE | AF20: FALSE | AG20: FALSE | AH20: FALSE | AI20: FALSE | AJ20: FALSE | AK20: FALSE | AL20: FALSE | AM20: FALSE | AN20: FALSE | AO20: FALSE | AP20: FALSE | AQ20: FALSE | AR20: FALSE | AS20: FALSE | AT20: FALSE | AU20: FALSE | AV20: FALSE | AW20: FALSE | AX20: FALSE | AY20: FALSE | AZ20: FALSE | BA20: FALSE | BB20: FALSE | BC20: FALSE | BD20: FALSE | BE20: FALSE | BF20: FALSE | BG20: FALSE | BH20: FALSE | BI20: FALSE | BJ20: FALSE | BK20: FALSE | BL20: FALSE | BM20: FALSE | BN20: FALSE | BO20: FALSE
A21: =A20&C21 -> AprilPINU OT HOURS | C21: OT HOURS | E21: =SUM(F21:BO21) -> 15 | F21: 2 | H21: 5 | L21: 4 | N21: 2 | R21: 2
A22: =B22&D22 -> AprilSANJAY BAGARTTI.K | B22: April | C22: PR 05 | D22: =IFERROR(VLOOKUP(C22,'Employees List'!$B$2:$E1424,4,0),"") -> SANJAY BAGARTTI.K | E22: =COUNTIF(F22:BO22,TRUE)/2 -> 30 | F22: TRUE | G22: TRUE | H22: TRUE | I22: TRUE | J22: TRUE | K22: TRUE | L22: TRUE | M22: TRUE | N22: TRUE | O22: TRUE | P22: TRUE | Q22: TRUE | R22: TRUE | S22: TRUE | T22: TRUE | U22: TRUE | V22: TRUE | W22: TRUE | X22: TRUE | Y22: TRUE | Z22: TRUE | AA22: TRUE | AB22: TRUE | AC22: TRUE | AD22: TRUE | AE22: TRUE | AF22: TRUE | AG22: TRUE | AH22: TRUE | AI22: TRUE | AJ22: TRUE | AK22: TRUE | AL22: TRUE | AM22: TRUE | AN22: TRUE | AO22: TRUE | AP22: TRUE | AQ22: TRUE | AR22: TRUE | AS22: TRUE | AT22: TRUE | AU22: TRUE | AV22: TRUE | AW22: TRUE | AX22: TRUE | AY22: TRUE | AZ22: TRUE | BA22: TRUE | BB22: TRUE | BC22: TRUE | BD22: TRUE | BE22: TRUE | BF22: TRUE | BG22: TRUE | BH22: TRUE | BI22: TRUE | BJ22: TRUE | BK22: TRUE | BL22: TRUE | BM22: TRUE | BN22: FALSE | BO22: FALSE
A23: =A22&C23 -> AprilSANJAY BAGARTTI.KOT HOURS | C23: OT HOURS | E23: =SUM(F23:BO23) -> 87 | F23: 2 | H23: 2 | L23: 2 | N23: 2 | P23: 3 | R23: 2 | T23: 3 | V23: 2 | X23: 3 | Z23: 2 | AB23: 2 | AH23: 6 | AJ23: 4 | AL23: 2 | AN23: 4 | AP23: 6 | AT23: 7 | AV23: 8 | AX23: 6 | AZ23: 4 | BB23: 2 | BD23: 6 | BJ23: 3 | BL23: 4
A24: =B24&D24 -> AprilADHIKARI BALIA.A | B24: April | C24: PR 03 | D24: =IFERROR(VLOOKUP(C24,'Employees List'!$B$2:$E1424,4,0),"") -> ADHIKARI BALIA.A | E24: =COUNTIF(F24:BO24,TRUE)/2 -> 10 | F24: FALSE | G24: FALSE | H24: FALSE | I24: FALSE | J24: FALSE | K24: FALSE | L24: FALSE | M24: FALSE | N24: FALSE | O24: FALSE | P24: FALSE | Q24: FALSE | R24: FALSE | S24: FALSE | T24: FALSE | U24: FALSE | V24: FALSE | W24: FALSE | X24: FALSE | Y24: FALSE | Z24: FALSE | AA24: FALSE | AB24: FALSE | AC24: FALSE | AD24: FALSE | AE24: FALSE | AF24: FALSE | AG24: FALSE | AH24: FALSE | AI24: FALSE | AJ24: FALSE | AK24: FALSE | AL24: FALSE | AM24: FALSE | AN24: FALSE | AO24: FALSE | AP24: FALSE | AQ24: FALSE | AR24: FALSE | AS24: FALSE | AT24: TRUE | AU24: TRUE | AV24: TRUE | AW24: TRUE | AX24: TRUE | AY24: TRUE | AZ24: TRUE | BA24: TRUE | BB24: TRUE | BC24: TRUE | BD24: TRUE | BE24: TRUE | BF24: TRUE | BG24: TRUE | BH24: TRUE | BI24: TRUE | BJ24: TRUE | BK24: TRUE | BL24: TRUE | BM24: TRUE | BN24: FALSE | BO24: FALSE
A25: =A24&C25 -> AprilADHIKARI BALIA.AOT HOURS | C25: OT HOURS | E25: =SUM(F25:BO25) -> 34 | AT25: 5 | AV25: 8 | AX25: 4 | AZ25: 4 | BD25: 6 | BJ25: 3 | BL25: 4
A26: =B26&D26 -> AprilRUPESH KISAN | B26: April | C26: PR 04 | D26: =IFERROR(VLOOKUP(C26,'Employees List'!$B$2:$E1424,4,0),"") -> RUPESH KISAN | E26: =COUNTIF(F26:BO26,TRUE)/2 -> 10 | F26: FALSE | G26: FALSE | H26: FALSE | I26: FALSE | J26: FALSE | K26: FALSE | L26: FALSE | M26: FALSE | N26: FALSE | O26: FALSE | P26: FALSE | Q26: FALSE | R26: FALSE | S26: FALSE | T26: FALSE | U26: FALSE | V26: FALSE | W26: FALSE | X26: FALSE | Y26: FALSE | Z26: FALSE | AA26: FALSE | AB26: FALSE | AC26: FALSE | AD26: FALSE | AE26: FALSE | AF26: FALSE | AG26: FALSE | AH26: FALSE | AI26: FALSE | AJ26: FALSE | AK26: FALSE | AL26: FALSE | AM26: FALSE | AN26: FALSE | AO26: FALSE | AP26: FALSE | AQ26: FALSE | AR26: FALSE | AS26: FALSE | AT26: TRUE | AU26: TRUE | AV26: TRUE | AW26: TRUE | AX26: TRUE | AY26: TRUE | AZ26: TRUE | BA26: TRUE | BB26: TRUE | BC26: TRUE | BD26: TRUE | BE26: TRUE | BF26: TRUE | BG26: TRUE | BH26: TRUE | BI26: TRUE | BJ26: TRUE | BK26: TRUE | BL26: TRUE | BM26: TRUE | BN26: FALSE | BO26: FALSE
A27: =A26&C27 -> AprilRUPESH KISANOT HOURS | C27: OT HOURS | E27: =SUM(F27:BO27) -> 24 | AT27: 3 | AV27: 2 | AX27: 6 | AZ27: 6 | BJ27: 3 | BL27: 4
A28: =B28&D28 -> AprilLIPAN | B28: April | C28: PR 21 | D28: =IFERROR(VLOOKUP(C28,'Employees List'!$B$2:$E1424,4,0),"") -> LIPAN | E28: =COUNTIF(F28:BO28,TRUE)/2 -> 10 | F28: FALSE | G28: FALSE | H28: FALSE | I28: FALSE | J28: FALSE | K28: FALSE | L28: FALSE | M28: FALSE | N28: FALSE | O28: FALSE | P28: FALSE | Q28: FALSE | R28: FALSE | S28: FALSE | T28: FALSE | U28: FALSE | V28: FALSE | W28: FALSE | X28: FALSE | Y28: FALSE | Z28: FALSE | AA28: FALSE | AB28: FALSE | AC28: FALSE | AD28: FALSE | AE28: FALSE | AF28: FALSE | AG28: FALSE | AH28: FALSE | AI28: FALSE | AJ28: FALSE | AK28: FALSE | AL28: FALSE | AM28: FALSE | AN28: FALSE | AO28: FALSE | AP28: FALSE | AQ28: FALSE | AR28: FALSE | AS28: FALSE | AT28: TRUE | AU28: TRUE | AV28: TRUE | AW28: TRUE | AX28: TRUE | AY28: TRUE | AZ28: TRUE | BA28: TRUE | BB28: TRUE | BC28: TRUE | BD28: TRUE | BE28: TRUE | BF28: TRUE | BG28: TRUE | BH28: TRUE | BI28: TRUE | BJ28: TRUE | BK28: TRUE | BL28: TRUE | BM28: TRUE | BN28: FALSE | BO28: FALSE
A29: =A28&C29 -> AprilLIPANOT HOURS | C29: OT HOURS | E29: =SUM(F29:BO29) -> 38 | AT29: 5 | AV29: 8 | AX29: 6 | AZ29: 6 | BD29: 6 | BJ29: 3 | BL29: 4
A30: =B30&D30 -> AprilNILAMANI KISAN.B | B30: April | C30: PR 24 | D30: =IFERROR(VLOOKUP(C30,'Employees List'!$B$2:$E1424,4,0),"") -> NILAMANI KISAN.B | E30: =COUNTIF(F30:BO30,TRUE)/2 -> 27 | F30: FALSE | G30: FALSE | H30: FALSE | I30: FALSE | J30: FALSE | K30: FALSE | L30: TRUE | M30: TRUE | N30: TRUE | O30: TRUE | P30: TRUE | Q30: TRUE | R30: TRUE | S30: TRUE | T30: TRUE | U30: TRUE | V30: TRUE | W30: TRUE | X30: TRUE | Y30: TRUE | Z30: TRUE | AA30: TRUE | AB30: TRUE | AC30: TRUE | AD30: TRUE | AE30: TRUE | AF30: TRUE | AG30: TRUE | AH30: TRUE | AI30: TRUE | AJ30: TRUE | AK30: TRUE | AL30: TRUE | AM30: TRUE | AN30: TRUE | AO30: TRUE | AP30: TRUE | AQ30: TRUE | AR30: TRUE | AS30: TRUE | AT30: TRUE | AU30: TRUE | AV30: TRUE | AW30: TRUE | AX30: TRUE | AY30: TRUE | AZ30: TRUE | BA30: TRUE | BB30: TRUE | BC30: TRUE | BD30: TRUE | BE30: TRUE | BF30: TRUE | BG30: TRUE | BH30: TRUE | BI30: TRUE | BJ30: TRUE | BK30: TRUE | BL30: TRUE | BM30: TRUE | BN30: FALSE | BO30: FALSE
A31: =A30&C31 -> AprilNILAMANI KISAN.BOT HOURS | C31: OT HOURS | E31: =SUM(F31:BO31) -> 40 | N31: 2 | R31: 2 | T31: 2 | V31: 2 | X31: 2 | AH31: 2 | AJ31: 4 | AL31: 2 | AN31: 4 | AP31: 6 | AT31: 3 | AV31: 2 | AX31: 2 | AZ31: 2 | BJ31: 3
C34: 45778
C35: Employee Code | D35: Name | E35: Days Present / OT Hours | F35: M | G35: A | H35: M | I35: A | J35: M | K35: A | L35: M | M35: A | N35: M | O35: A | P35: M | Q35: A | R35: M | S35: A | T35: M | U35: A | V35: M | W35: A | X35: M | Y35: A | Z35: M | AA35: A | AB35: M | AC35: A | AD35: M | AE35: A | AF35: M | AG35: A | AH35: M | AI35: A | AJ35: M | AK35: A | AL35: M | AM35: A | AN35: M | AO35: A | AP35: M | AQ35: A | AR35: M | AS35: A | AT35: M | AU35: A | AV35: M | AW35: A | AX35: M | AY35: A | AZ35: M | BA35: A | BB35: M | BC35: A | BD35: M | BE35: A | BF35: M | BG35: A | BH35: M | BI35: A | BJ35: M | BK35: A | BL35: M | BM35: A | BN35: M | BO35: A
A36: =B36&D36 -> MayBHUVANESHWARAN.V | B36: May | C36: AC 01 | D36: =IFERROR(VLOOKUP(C36,'Employees List'!$B$2:$E1424,4,0),"") -> BHUVANESHWARAN.V | E36: =COUNTIF(F36:BO36,TRUE)/2 -> 31 | F36: TRUE | G36: TRUE | H36: TRUE | I36: TRUE | J36: TRUE | K36: TRUE | L36: TRUE | M36: TRUE | N36: TRUE | O36: TRUE | P36: TRUE | Q36: TRUE | R36: TRUE | S36: TRUE | T36: TRUE | U36: TRUE | V36: TRUE | W36: TRUE | X36: TRUE | Y36: TRUE | Z36: TRUE | AA36: TRUE | AB36: TRUE | AC36: TRUE | AD36: TRUE | AE36: TRUE | AF36: TRUE | AG36: TRUE | AH36: TRUE | AI36: TRUE | AJ36: TRUE | AK36: TRUE | AL36: TRUE | AM36: TRUE | AN36: TRUE | AO36: TRUE | AP36: TRUE | AQ36: TRUE | AR36: TRUE | AS36: TRUE | AT36: TRUE | AU36: TRUE | AV36: TRUE | AW36: TRUE | AX36: TRUE | AY36: TRUE | AZ36: TRUE | BA36: TRUE | BB36: TRUE | BC36: TRUE | BD36: TRUE | BE36: TRUE | BF36: TRUE | BG36: TRUE | BH36: TRUE | BI36: TRUE | BJ36: TRUE | BK36: TRUE | BL36: TRUE | BM36: TRUE | BN36: TRUE | BO36: TRUE
A37: =A36&C37 -> MayBHUVANESHWARAN.VOT HOURS | C37: OT HOURS | E37: =SUM(F37:BO37) -> 0
A38: =B38&D38 -> MayTHIRIPURA SUNDARI.R | B38: May | C38: AC 02 | D38: =IFERROR(VLOOKUP(C38,'Employees List'!$B$2:$E1424,4,0),"") -> THIRIPURA SUNDARI.R | E38: =COUNTIF(F38:BO38,TRUE)/2 -> 31 | F38: TRUE | G38: TRUE | H38: TRUE | I38: TRUE | J38: TRUE | K38: TRUE | L38: TRUE | M38: TRUE | N38: TRUE | O38: TRUE | P38: TRUE | Q38: TRUE | R38: TRUE | S38: TRUE | T38: TRUE | U38: TRUE | V38: TRUE | W38: TRUE | X38: TRUE | Y38: TRUE | Z38: TRUE | AA38: TRUE | AB38: TRUE | AC38: TRUE | AD38: TRUE | AE38: TRUE | AF38: TRUE | AG38: TRUE | AH38: TRUE | AI38: TRUE | AJ38: TRUE | AK38: TRUE | AL38: TRUE | AM38: TRUE | AN38: TRUE | AO38: TRUE | AP38: TRUE | AQ38: TRUE | AR38: TRUE | AS38: TRUE | AT38: TRUE | AU38: TRUE | AV38: TRUE | AW38: TRUE | AX38: TRUE | AY38: TRUE | AZ38: TRUE | BA38: TRUE | BB38: TRUE | BC38: TRUE | BD38: TRUE | BE38: TRUE | BF38: TRUE | BG38: TRUE | BH38: TRUE | BI38: TRUE | BJ38: TRUE | BK38: TRUE | BL38: TRUE | BM38: TRUE | BN38: TRUE | BO38: TRUE
A39: =A38&C39 -> MayTHIRIPURA SUNDARI.ROT HOURS | C39: OT HOURS | E39: =SUM(F39:BO39) -> 10 | N39: 1 | P39: 1 | R39: 1 | X39: 1 | AL39: 2 | AR39: 1 | BD39: 1 | BF39: 2
A40: =B40&D40 -> MayGANESH | B40: May | C40: PR 02 | D40: =IFERROR(VLOOKUP(C40,'Employees List'!$B$2:$E1424,4,0),"") -> GANESH | E40: =COUNTIF(F40:BO40,TRUE)/2 -> 24.5 | F40: TRUE | G40: TRUE | H40: TRUE | I40: TRUE | J40: TRUE | K40: TRUE | L40: TRUE | M40: TRUE | N40: TRUE | O40: TRUE | P40: TRUE | Q40: TRUE | R40: TRUE | S40: TRUE | T40: TRUE | U40: TRUE | V40: TRUE | W40: TRUE | X40: TRUE | Y40: TRUE | Z40: TRUE | AA40: TRUE | AB40: FALSE | AC40: FALSE | AD40: TRUE | AE40: TRUE | AF40: TRUE | AG40: FALSE | AH40: FALSE | AI40: FALSE | AJ40: FALSE | AK40: FALSE | AL40: FALSE | AM40: FALSE | AN40: FALSE | AO40: FALSE | AP40: FALSE | AQ40: FALSE | AR40: TRUE | AS40: TRUE | AT40: TRUE | AU40: TRUE | AV40: TRUE | AW40: TRUE | AX40: TRUE | AY40: TRUE | AZ40: TRUE | BA40: TRUE | BB40: TRUE | BC40: TRUE | BD40: TRUE | BE40: TRUE | BF40: TRUE | BG40: TRUE | BH40: TRUE | BI40: TRUE | BJ40: TRUE | BK40: TRUE | BL40: TRUE | BM40: TRUE | BN40: TRUE | BO40: TRUE
A41: =A40&C41 -> MayGANESHOT HOURS | C41: OT HOURS | E41: =SUM(F41:BO41) -> 45 | J41: 2 | P41: 2 | T41: 4 | V41: 3 | X41: 2 | AD41: 3 | AR41: 2 | AT41: 4 | AV41: 2 | AX41: 2 | AZ41: 7 | BD41: 3 | BF41: 3 | BH41: 2 | BJ41: 2 | BN41: 2
A42: =B42&D42 -> MayILAMATHIVANAN.S | B42: May | C42: DR 01 | D42: =IFERROR(VLOOKUP(C42,'Employees List'!$B$2:$E1424,4,0),"") -> ILAMATHIVANAN.S | E42: =COUNTIF(F42:BO42,TRUE)/2 -> 28.5 | F42: TRUE | G42: TRUE | H42: TRUE | I42: TRUE | J42: FALSE | K42: TRUE | L42: TRUE | M42: TRUE | N42: TRUE | O42: TRUE | P42: TRUE | Q42: TRUE | R42: TRUE | S42: TRUE | T42: FALSE | U42: FALSE | V42: TRUE | W42: TRUE | X42: TRUE | Y42: TRUE | Z42: TRUE | AA42: TRUE | AB42: TRUE | AC42: TRUE | AD42: TRUE | AE42: TRUE | AF42: TRUE | AG42: TRUE | AH42: TRUE | AI42: TRUE | AJ42: FALSE | AK42: FALSE | AL42: TRUE | AM42: TRUE | AN42: TRUE | AO42: TRUE | AP42: TRUE | AQ42: TRUE | AR42: TRUE | AS42: TRUE | AT42: TRUE | AU42: TRUE | AV42: TRUE | AW42: TRUE | AX42: TRUE | AY42: TRUE | AZ42: TRUE | BA42: TRUE | BB42: TRUE | BC42: TRUE | BD42: TRUE | BE42: TRUE | BF42: TRUE | BG42: TRUE | BH42: TRUE | BI42: TRUE | BJ42: TRUE | BK42: TRUE | BL42: TRUE | BM42: TRUE | BN42: TRUE | BO42: TRUE
...

Sheet Attendance Report
A1: Emp Id | B1: Name | O1: April | P1: May | Q1: June | R1: July | S1: August | T1: September | U1: October | V1: November | W1: December | X1: January | Y1: February | Z1: March | AA1: Total Present
A2: AC 01 | B2: =IFERROR(VLOOKUP(A2,'Employees List'!$B$2:E981,4,0),"") -> BHUVANESHWARAN.V | C2: =$O$1&B2 -> AprilBHUVANESHWARAN.V | D2: =$P$1&B2 -> MayBHUVANESHWARAN.V | E2: =$Q$1&B2 -> JuneBHUVANESHWARAN.V | F2: =$R$1&B2 -> JulyBHUVANESHWARAN.V | G2: =$S$1&B2 -> AugustBHUVANESHWARAN.V | H2: =$T$1&B2 -> SeptemberBHUVANESHWARAN.V | I2: =$U$1&B2 -> OctoberBHUVANESHWARAN.V | J2: =$V$1&B2 -> NovemberBHUVANESHWARAN.V | K2: =$W$1&B2 -> DecemberBHUVANESHWARAN.V | L2: =$X$1&B2 -> JanuaryBHUVANESHWARAN.V | M2: =$Y$1&B2 -> FebruaryBHUVANESHWARAN.V | N2: =$Z$1&B2 -> MarchBHUVANESHWARAN.V | O2: =IFERROR(VLOOKUP(C2,'Daily Attendance 25-26'!$A$1:BP981,5,0),"") -> 30 | P2: =IFERROR(VLOOKUP(D2,'Daily Attendance 25-26'!$A$1:BP981,5,0),"") -> 31 | Q2: =IFERROR(VLOOKUP(E2,'Daily Attendance 25-26'!$A$1:BP981,5,0),"") -> 30 | R2: =IFERROR(VLOOKUP(F2,'Daily Attendance 25-26'!$A$1:BP981,5,0),"") -> 31 | S2: =IFERROR(VLOOKUP(G2,'Daily Attendance 25-26'!$A$1:BP981,5,0),"") -> 31 | T2: =IFERROR(VLOOKUP(H2,'Daily Attendance 25-26'!$A$1:BP981,5,0),"") | U2: =IFERROR(VLOOKUP(I2,'Daily Attendance 25-26'!$A$1:BP981,5,0),"") | V2: =IFERROR(VLOOKUP(J2,'Daily Attendance 25-26'!$A$1:BP981,5,0),"") -> 30 | W2: =IFERROR(VLOOKUP(K2,'Daily Attendance 25-26'!$A$1:BP981,5,0),"") -> 31 | X2: =IFERROR(VLOOKUP(L2,'Daily Attendance 25-26'!$A$1:BP981,5,0),"") -> 31 | Y2: =IFERROR(VLOOKUP(M2,'Daily Attendance 25-26'!$A$1:BP981,5,0),"") -> 28 | Z2: =IFERROR(VLOOKUP(N2,'Daily Attendance 25-26'!$A$1:BP981,5,0),"") | AA2: =SUM(D2:Z2) -> 273
A3: AC 02 | B3: =IFERROR(VLOOKUP(A3,'Employees List'!$B$2:E981,4,0),"") -> THIRIPURA SUNDARI.R | C3: =$O$1&B3 -> AprilTHIRIPURA SUNDARI.R | D3: =$P$1&B3 -> MayTHIRIPURA SUNDARI.R | E3: =$Q$1&B3 -> JuneTHIRIPURA SUNDARI.R | F3: =$R$1&B3 -> JulyTHIRIPURA SUNDARI.R | G3: =$S$1&B3 -> AugustTHIRIPURA SUNDARI.R | H3: =$T$1&B3 -> SeptemberTHIRIPURA SUNDARI.R | I3: =$U$1&B3 -> OctoberTHIRIPURA SUNDARI.R | J3: =$V$1&B3 -> NovemberTHIRIPURA SUNDARI.R | K3: =$W$1&B3 -> DecemberTHIRIPURA SUNDARI.R | L3: =$X$1&B3 -> JanuaryTHIRIPURA SUNDARI.R | M3: =$Y$1&B3 -> FebruaryTHIRIPURA SUNDARI.R | N3: =$Z$1&B3 -> MarchTHIRIPURA SUNDARI.R | O3: =IFERROR(VLOOKUP(C3,'Daily Attendance 25-26'!$A$1:BP981,5,0),"") -> 30 | P3: =IFERROR(VLOOKUP(D3,'Daily Attendance 25-26'!$A$1:BP981,5,0),"") -> 31 | Q3: =IFERROR(VLOOKUP(E3,'Daily Attendance 25-26'!$A$1:BP981,5,0),"") -> 30 | R3: =IFERROR(VLOOKUP(F3,'Daily Attendance 25-26'!$A$1:BP981,5,0),"") -> 25 | S3: =IFERROR(VLOOKUP(G3,'Daily Attendance 25-26'!$A$1:BP981,5,0),"") -> 29 | T3: =IFERROR(VLOOKUP(H3,'Daily Attendance 25-26'!$A$1:BP981,5,0),"") | U3: =IFERROR(VLOOKUP(I3,'Daily Attendance 25-26'!$A$1:BP981,5,0),"") | V3: =IFERROR(VLOOKUP(J3,'Daily Attendance 25-26'!$A$1:BP981,5,0),"") -> 30 | W3: =IFERROR(VLOOKUP(K3,'Daily Attendance 25-26'!$A$1:BP981,5,0),"") -> 31 | X3: =IFERROR(VLOOKUP(L3,'Daily Attendance 25-26'!$A$1:BP981,5,0),"") -> 31 | Y3: =IFERROR(VLOOKUP(M3,'Daily Attendance 25-26'!$A$1:BP981,5,0),"") -> 28 | Z3: =IFERROR(VLOOKUP(N3,'Daily Attendance 25-26'!$A$1:BP981,5,0),"") | AA3: =SUM(D3:Z3) -> 265
A4: PR 02 | B4: =IFERROR(VLOOKUP(A4,'Employees List'!$B$2:E981,4,0),"") -> GANESH | C4: =$O$1&B4 -> AprilGANESH | D4: =$P$1&B4 -> MayGANESH | E4: =$Q$1&B4 -> JuneGANESH | F4: =$R$1&B4 -> JulyGANESH | G4: =$S$1&B4 -> AugustGANESH | H4: =$T$1&B4 -> SeptemberGANESH | I4: =$U$1&B4 -> OctoberGANESH | J4: =$V$1&B4 -> NovemberGANESH | K4: =$W$1&B4 -> DecemberGANESH | L4: =$X$1&B4 -> JanuaryGANESH | M4: =$Y$1&B4 -> FebruaryGANESH | N4: =$Z$1&B4 -> MarchGANESH | O4: =IFERROR(VLOOKUP(C4,'Daily Attendance 25-26'!$A$1:BP981,5,0),"") -> 22 | P4: =IFERROR(VLOOKUP(D4,'Daily Attendance 25-26'!$A$1:BP981,5,0),"") -> 24.5 | Q4: =IFERROR(VLOOKUP(E4,'Daily Attendance 25-26'!$A$1:BP981,5,0),"") -> 25 | R4: =IFERROR(VLOOKUP(F4,'Daily Attendance 25-26'!$A$1:BP981,5,0),"") -> 22 | S4: =IFERROR(VLOOKUP(G4,'Daily Attendance 25-26'!$A$1:BP981,5,0),"") -> 29 | T4: =IFERROR(VLOOKUP(H4,'Daily Attendance 25-26'!$A$1:BP981,5,0),"") | U4: =IFERROR(VLOOKUP(I4,'Daily Attendance 25-26'!$A$1:BP981,5,0),"") | V4: =IFERROR(VLOOKUP(J4,'Daily Attendance 25-26'!$A$1:BP981,5,0),"") -> 24 | W4: =IFERROR(VLOOKUP(K4,'Daily Attendance 25-26'!$A$1:BP981,5,0),"") -> 26 | X4: =IFERROR(VLOOKUP(L4,'Daily Attendance 25-26'!$A$1:BP981,5,0),"") -> 25 | Y4: =IFERROR(VLOOKUP(M4,'Daily Attendance 25-26'!$A$1:BP981,5,0),"") -> 25 | Z4: =IFERROR(VLOOKUP(N4,'Daily Attendance 25-26'!$A$1:BP981,5,0),"") | AA4: =SUM(D4:Z4) -> 222.5
A5: DR 01 | B5: =IFERROR(VLOOKUP(A5,'Employees List'!$B$2:E981,4,0),"") -> ILAMATHIVANAN.S | C5: =$O$1&B5 -> AprilILAMATHIVANAN.S | D5: =$P$1&B5 -> MayILAMATHIVANAN.S | E5: =$Q$1&B5 -> JuneILAMATHIVANAN.S | F5: =$R$1&B5 -> JulyILAMATHIVANAN.S | G5: =$S$1&B5 -> AugustILAMATHIVANAN.S | H5: =$T$1&B5 -> SeptemberILAMATHIVANAN.S | I5: =$U$1&B5 -> OctoberILAMATHIVANAN.S | J5: =$V$1&B5 -> NovemberILAMATHIVANAN.S | K5: =$W$1&B5 -> DecemberILAMATHIVANAN.S | L5: =$X$1&B5 -> JanuaryILAMATHIVANAN.S | M5: =$Y$1&B5 -> FebruaryILAMATHIVANAN.S | N5: =$Z$1&B5 -> MarchILAMATHIVANAN.S | O5: =IFERROR(VLOOKUP(C5,'Daily Attendance 25-26'!$A$1:BP981,5,0),"") -> 23 | P5: =IFERROR(VLOOKUP(D5,'Daily Attendance 25-26'!$A$1:BP981,5,0),"") -> 28.5 | Q5: =IFERROR(VLOOKUP(E5,'Daily Attendance 25-26'!$A$1:BP981,5,0),"") -> 22 | R5: =IFERROR(VLOOKUP(F5,'Daily Attendance 25-26'!$A$1:BP981,5,0),"") -> 5 | S5: =IFERROR(VLOOKUP(G5,'Daily Attendance 25-26'!$A$1:BP981,5,0),"") -> 0 | T5: =IFERROR(VLOOKUP(H5,'Daily Attendance 25-26'!$A$1:BP981,5,0),"") | U5: =IFERROR(VLOOKUP(I5,'Daily Attendance 25-26'!$A$1:BP981,5,0),"") | V5: =IFERROR(VLOOKUP(J5,'Daily Attendance 25-26'!$A$1:BP981,5,0),"") -> 0 | W5: =IFERROR(VLOOKUP(K5,'Daily Attendance 25-26'!$A$1:BP981,5,0),"") | X5: =IFERROR(VLOOKUP(L5,'Daily Attendance 25-26'!$A$1:BP981,5,0),"") | Y5: =IFERROR(VLOOKUP(M5,'Daily Attendance 25-26'!$A$1:BP981,5,0),"") | Z5: =IFERROR(VLOOKUP(N5,'Daily Attendance 25-26'!$A$1:BP981,5,0),"") | AA5: =SUM(D5:Z5) -> 78.5
A6: PR 07 | B6: =IFERROR(VLOOKUP(A6,'Employees List'!$B$2:E981,4,0),"") -> AMMU.S | C6: =$O$1&B6 -> AprilAMMU.S | D6: =$P$1&B6 -> MayAMMU.S | E6: =$Q$1&B6 -> JuneAMMU.S | F6: =$R$1&B6 -> JulyAMMU.S | G6: =$S$1&B6 -> AugustAMMU.S | H6: =$T$1&B6 -> SeptemberAMMU.S | I6: =$U$1&B6 -> OctoberAMMU.S | J6: =$V$1&B6 -> NovemberAMMU.S | K6: =$W$1&B6 -> DecemberAMMU.S | L6: =$X$1&B6 -> JanuaryAMMU.S | M6: =$Y$1&B6 -> FebruaryAMMU.S | N6: =$Z$1&B6 -> MarchAMMU.S | O6: =IFERROR(VLOOKUP(C6,'Daily Attendance 25-26'!$A$1:BP981,5,0),"") -> 30 | P6: =IFERROR(VLOOKUP(D6,'Daily Attendance 25-26'!$A$1:BP981,5,0),"") -> 27 | Q6: =IFERROR(VLOOKUP(E6,'Daily Attendance 25-26'!$A$1:BP981,5,0),"") -> 28 | R6: =IFERROR(VLOOKUP(F6,'Daily Attendance 25-26'!$A$1:BP981,5,0),"") -> 23 | S6: =IFERROR(VLOOKUP(G6,'Daily Attendance 25-26'!$A$1:BP981,5,0),"") -> 31 | T6: =IFERROR(VLOOKUP(H6,'Daily Attendance 25-26'!$A$1:BP981,5,0),"") | U6: =IFERROR(VLOOKUP(I6,'Daily Attendance 25-26'!$A$1:BP981,5,0),"") | V6: =IFERROR(VLOOKUP(J6,'Daily Attendance 25-26'!$A$1:BP981,5,0),"") -> 28 | W6: =IFERROR(VLOOKUP(K6,'Daily Attendance 25-26'!$A$1:BP981,5,0),"") -> 29 | X6: =IFERROR(VLOOKUP(L6,'Daily Attendance 25-26'!$A$1:BP981,5,0),"") -> 28 | Y6: =IFERROR(VLOOKUP(M6,'Daily Attendance 25-26'!$A$1:BP981,5,0),"") -> 28 | Z6: =IFERROR(VLOOKUP(N6,'Daily Attendance 25-26'!$A$1:BP981,5,0),"") | AA6: =SUM(D6:Z6) -> 252
A7: PR 08 | B7: =IFERROR(VLOOKUP(A7,'Employees List'!$B$2:E981,4,0),"") -> REVATHI.S | C7: =$O$1&B7 -> AprilREVATHI.S | D7: =$P$1&B7 -> MayREVATHI.S | E7: =$Q$1&B7 -> JuneREVATHI.S | F7: =$R$1&B7 -> JulyREVATHI.S | G7: =$S$1&B7 -> AugustREVATHI.S | H7: =$T$1&B7 -> SeptemberREVATHI.S | I7: =$U$1&B7 -> OctoberREVATHI.S | J7: =$V$1&B7 -> NovemberREVATHI.S | K7: =$W$1&B7 -> DecemberREVATHI.S | L7: =$X$1&B7 -> JanuaryREVATHI.S | M7: =$Y$1&B7 -> FebruaryREVATHI.S | N7: =$Z$1&B7 -> MarchREVATHI.S | O7: =IFERROR(VLOOKUP(C7,'Daily Attendance 25-26'!$A$1:BP981,5,0),"") -> 29 | P7: =IFERROR(VLOOKUP(D7,'Daily Attendance 25-26'!$A$1:BP981,5,0),"") -> 30 | Q7: =IFERROR(VLOOKUP(E7,'Daily Attendance 25-26'!$A$1:BP981,5,0),"") -> 29 | R7: =IFERROR(VLOOKUP(F7,'Daily Attendance 25-26'!$A$1:BP981,5,0),"") -> 30 | S7: =IFERROR(VLOOKUP(G7,'Daily Attendance 25-26'!$A$1:BP981,5,0),"") -> 29 | T7: =IFERROR(VLOOKUP(H7,'Daily Attendance 25-26'!$A$1:BP981,5,0),"") | U7: =IFERROR(VLOOKUP(I7,'Daily Attendance 25-26'!$A$1:BP981,5,0),"") | V7: =IFERROR(VLOOKUP(J7,'Daily Attendance 25-26'!$A$1:BP981,5,0),"") -> 27 | W7: =IFERROR(VLOOKUP(K7,'Daily Attendance 25-26'!$A$1:BP981,5,0),"") -> 30 | X7: =IFERROR(VLOOKUP(L7,'Daily Attendance 25-26'!$A$1:BP981,5,0),"") -> 26 | Y7: =IFERROR(VLOOKUP(M7,'Daily Attendance 25-26'!$A$1:BP981,5,0),"") -> 25 | Z7: =IFERROR(VLOOKUP(N7,'Daily Attendance 25-26'!$A$1:BP981,5,0),"") | AA7: =SUM(D7:Z7) -> 255
A8: AC 03 | B8: =IFERROR(VLOOKUP(A8,'Employees List'!$B$2:E981,4,0),"") -> LEELAVATHI.M | C8: =$O$1&B8 -> AprilLEELAVATHI.M | D8: =$P$1&B8 -> MayLEELAVATHI.M | E8: =$Q$1&B8 -> JuneLEELAVATHI.M | F8: =$R$1&B8 -> JulyLEELAVATHI.M | G8: =$S$1&B8 -> AugustLEELAVATHI.M | H8: =$T$1&B8 -> SeptemberLEELAVATHI.M | I8: =$U$1&B8 -> OctoberLEELAVATHI.M | J8: =$V$1&B8 -> NovemberLEELAVATHI.M | K8: =$W$1&B8 -> DecemberLEELAVATHI.M | L8: =$X$1&B8 -> JanuaryLEELAVATHI.M | M8: =$Y$1&B8 -> FebruaryLEELAVATHI.M | N8: =$Z$1&B8 -> MarchLEELAVATHI.M | O8: =IFERROR(VLOOKUP(C8,'Daily Attendance 25-26'!$A$1:BP981,5,0),"") -> 30 | P8: =IFERROR(VLOOKUP(D8,'Daily Attendance 25-26'!$A$1:BP981,5,0),"") -> 29 | Q8: =IFERROR(VLOOKUP(E8,'Daily Attendance 25-26'!$A$1:BP981,5,0),"") -> 29 | R8: =IFERROR(VLOOKUP(F8,'Daily Attendance 25-26'!$A$1:BP981,5,0),"") -> 30 | S8: =IFERROR(VLOOKUP(G8,'Daily Attendance 25-26'!$A$1:BP981,5,0),"") -> 30 | T8: =IFERROR(VLOOKUP(H8,'Daily Attendance 25-26'!$A$1:BP981,5,0),"") | U8: =IFERROR(VLOOKUP(I8,'Daily Attendance 25-26'!$A$1:BP981,5,0),"") | V8: =IFERROR(VLOOKUP(J8,'Daily Attendance 25-26'!$A$1:BP981,5,0),"") -> 30 | W8: =IFERROR(VLOOKUP(K8,'Daily Attendance 25-26'!$A$1:BP981,5,0),"") -> 31 | X8: =IFERROR(VLOOKUP(L8,'Daily Attendance 25-26'!$A$1:BP981,5,0),"") -> 31 | Y8: =IFERROR(VLOOKUP(M8,'Daily Attendance 25-26'!$A$1:BP981,5,0),"") -> 28 | Z8: =IFERROR(VLOOKUP(N8,'Daily Attendance 25-26'!$A$1:BP981,5,0),"") | AA8: =SUM(D8:Z8) -> 268
A9: PR 27 | B9: =IFERROR(VLOOKUP(A9,'Employees List'!$B$2:E981,4,0),"") -> PARSHU BAGH | C9: =$O$1&B9 -> AprilPARSHU BAGH | D9: =$P$1&B9 -> MayPARSHU BAGH | E9: =$Q$1&B9 -> JunePARSHU BAGH | F9: =$R$1&B9 -> JulyPARSHU BAGH | G9: =$S$1&B9 -> AugustPARSHU BAGH | H9: =$T$1&B9 -> SeptemberPARSHU BAGH | I9: =$U$1&B9 -> OctoberPARSHU BAGH | J9: =$V$1&B9 -> NovemberPARSHU BAGH | K9: =$W$1&B9 -> DecemberPARSHU BAGH | L9: =$X$1&B9 -> JanuaryPARSHU BAGH | M9: =$Y$1&B9 -> FebruaryPARSHU BAGH | N9: =$Z$1&B9 -> MarchPARSHU BAGH | O9: =IFERROR(VLOOKUP(C9,'Daily Attendance 25-26'!$A$1:BP981,5,0),"") -> 9 | P9: =IFERROR(VLOOKUP(D9,'Daily Attendance 25-26'!$A$1:BP981,5,0),"") | Q9: =IFERROR(VLOOKUP(E9,'Daily Attendance 25-26'!$A$1:BP981,5,0),"") | R9: =IFERROR(VLOOKUP(F9,'Daily Attendance 25-26'!$A$1:BP981,5,0),"") -> 24 | S9: =IFERROR(VLOOKUP(G9,'Daily Attendance 25-26'!$A$1:BP981,5,0),"") -> 4.5 | T9: =IFERROR(VLOOKUP(H9,'Daily Attendance 25-26'!$A$1:BP981,5,0),"") | U9: =IFERROR(VLOOKUP(I9,'Daily Attendance 25-26'!$A$1:BP981,5,0),"") | V9: =IFERROR(VLOOKUP(J9,'Daily Attendance 25-26'!$A$1:BP981,5,0),"") | W9: =IFERROR(VLOOKUP(K9,'Daily Attendance 25-26'!$A$1:BP981,5,0),"") | X9: =IFERROR(VLOOKUP(L9,'Daily Attendance 25-26'!$A$1:BP981,5,0),"") -> 26 | Y9: =IFERROR(VLOOKUP(M9,'Daily Attendance 25-26'!$A$1:BP981,5,0),"") -> 24 | Z9: =IFERROR(VLOOKUP(N9,'Daily Attendance 25-26'!$A$1:BP981,5,0),"") | AA9: =SUM(D9:Z9) -> 87.5
A10: PR 12 | B10: =IFERROR(VLOOKUP(A10,'Employees List'!$B$2:E981,4,0),"") -> PINU | C10: =$O$1&B10 -> AprilPINU | D10: =$P$1&B10 -> MayPINU | E10: =$Q$1&B10 -> JunePINU | F10: =$R$1&B10 -> JulyPINU | G10: =$S$1&B10 -> AugustPINU | H10: =$T$1&B10 -> SeptemberPINU | I10: =$U$1&B10 -> OctoberPINU | J10: =$V$1&B10 -> NovemberPINU | K10: =$W$1&B10 -> DecemberPINU | L10: =$X$1&B10 -> JanuaryPINU | M10: =$Y$1&B10 -> FebruaryPINU | N10: =$Z$1&B10 -> MarchPINU | O10: =IFERROR(VLOOKUP(C10,'Daily Attendance 25-26'!$A$1:BP981,5,0),"") -> 9 | P10: =IFERROR(VLOOKUP(D10,'Daily Attendance 25-26'!$A$1:BP981,5,0),"") | Q10: =IFERROR(VLOOKUP(E10,'Daily Attendance 25-26'!$A$1:BP981,5,0),"") | R10: =IFERROR(VLOOKUP(F10,'Daily Attendance 25-26'!$A$1:BP981,5,0),"") | S10: =IFERROR(VLOOKUP(G10,'Daily Attendance 25-26'!$A$1:BP981,5,0),"") | T10: =IFERROR(VLOOKUP(H10,'Daily Attendance 25-26'!$A$1:BP981,5,0),"") | U10: =IFERROR(VLOOKUP(I10,'Daily Attendance 25-26'!$A$1:BP981,5,0),"") | V10: =IFERROR(VLOOKUP(J10,'Daily Attendance 25-26'!$A$1:BP981,5,0),"") | W10: =IFERROR(VLOOKUP(K10,'Daily Attendance 25-26'!$A$1:BP981,5,0),"") | X10: =IFERROR(VLOOKUP(L10,'Daily Attendance 25-26'!$A$1:BP981,5,0),"") | Y10: =IFERROR(VLOOKUP(M10,'Daily Attendance 25-26'!$A$1:BP981,5,0),"") | Z10: =IFERROR(VLOOKUP(N10,'Daily Attendance 25-26'!$A$1:BP981,5,0),"") | AA10: =SUM(D10:Z10) -> 9
A11: PR 05 | B11: =IFERROR(VLOOKUP(A11,'Employees List'!$B$2:E981,4,0),"") -> SANJAY BAGARTTI.K | C11: =$O$1&B11 -> AprilSANJAY BAGARTTI.K | D11: =$P$1&B11 -> MaySANJAY BAGARTTI.K | E11: =$Q$1&B11 -> JuneSANJAY BAGARTTI.K | F11: =$R$1&B11 -> JulySANJAY BAGARTTI.K | G11: =$S$1&B11 -> AugustSANJAY BAGARTTI.K | H11: =$T$1&B11 -> SeptemberSANJAY BAGARTTI.K | I11: =$U$1&B11 -> OctoberSANJAY BAGARTTI.K | J11: =$V$1&B11 -> NovemberSANJAY BAGARTTI.K | K11: =$W$1&B11 -> DecemberSANJAY BAGARTTI.K | L11: =$X$1&B11 -> JanuarySANJAY BAGARTTI.K | M11: =$Y$1&B11 -> FebruarySANJAY BAGARTTI.K | N11: =$Z$1&B11 -> MarchSANJAY BAGARTTI.K | O11: =IFERROR(VLOOKUP(C11,'Daily Attendance 25-26'!$A$1:BP981,5,0),"") -> 30 | P11: =IFERROR(VLOOKUP(D11,'Daily Attendance 25-26'!$A$1:BP981,5,0),"") -> 31 | Q11: =IFERROR(VLOOKUP(E11,'Daily Attendance 25-26'!$A$1:BP981,5,0),"") -> 29 | R11: =IFERROR(VLOOKUP(F11,'Daily Attendance 25-26'!$A$1:BP981,5,0),"") -> 31 | S11: =IFERROR(VLOOKUP(G11,'Daily Attendance 25-26'!$A$1:BP981,5,0),"") -> 30 | T11: =IFERROR(VLOOKUP(H11,'Daily Attendance 25-26'!$A$1:BP981,5,0),"") | U11: =IFERROR(VLOOKUP(I11,'Daily Attendance 25-26'!$A$1:BP981,5,0),"") | V11: =IFERROR(VLOOKUP(J11,'Daily Attendance 25-26'!$A$1:BP981,5,0),"") -> 30 | W11: =IFERROR(VLOOKUP(K11,'Daily Attendance 25-26'!$A$1:BP981,5,0),"") -> 19 | X11: =IFERROR(VLOOKUP(L11,'Daily Attendance 25-26'!$A$1:BP981,5,0),"") -> 26 | Y11: =IFERROR(VLOOKUP(M11,'Daily Attendance 25-26'!$A$1:BP981,5,0),"") -> 28 | Z11: =IFERROR(VLOOKUP(N11,'Daily Attendance 25-26'!$A$1:BP981,5,0),"") | AA11: =SUM(D11:Z11) -> 254
A12: PR 03 | B12: =IFERROR(VLOOKUP(A12,'Employees List'!$B$2:E981,4,0),"") -> ADHIKARI BALIA.A | C12: =$O$1&B12 -> AprilADHIKARI BALIA.A | D12: =$P$1&B12 -> MayADHIKARI BALIA.A | E12: =$Q$1&B12 -> JuneADHIKARI BALIA.A | F12: =$R$1&B12 -> JulyADHIKARI BALIA.A | G12: =$S$1&B12 -> AugustADHIKARI BALIA.A | H12: =$T$1&B12 -> SeptemberADHIKARI BALIA.A | I12: =$U$1&B12 -> OctoberADHIKARI BALIA.A | J12: =$V$1&B12 -> NovemberADHIKARI BALIA.A | K12: =$W$1&B12 -> DecemberADHIKARI BALIA.A | L12: =$X$1&B12 -> JanuaryADHIKARI BALIA.A | M12: =$Y$1&B12 -> FebruaryADHIKARI BALIA.A | N12: =$Z$1&B12 -> MarchADHIKARI BALIA.A | O12: =IFERROR(VLOOKUP(C12,'Daily Attendance 25-26'!$A$1:BP981,5,0),"") -> 10 | P12: =IFERROR(VLOOKUP(D12,'Daily Attendance 25-26'!$A$1:BP981,5,0),"") -> 31 | Q12: =IFERROR(VLOOKUP(E12,'Daily Attendance 25-26'!$A$1:BP981,5,0),"") -> 29 | R12: =IFERROR(VLOOKUP(F12,'Daily Attendance 25-26'!$A$1:BP981,5,0),"") -> 30 | S12: =IFERROR(VLOOKUP(G12,'Daily Attendance 25-26'!$A$1:BP981,5,0),"") -> 30 | T12: =IFERROR(VLOOKUP(H12,'Daily Attendance 25-26'!$A$1:BP981,5,0),"") | U12: =IFERROR(VLOOKUP(I12,'Daily Attendance 25-26'!$A$1:BP981,5,0),"") | V12: =IFERROR(VLOOKUP(J12,'Daily Attendance 25-26'!$A$1:BP981,5,0),"") | W12: =IFERROR(VLOOKUP(K12,'Daily Attendance 25-26'!$A$1:BP981,5,0),"") | X12: =IFERROR(VLOOKUP(L12,'Daily Attendance 25-26'!$A$1:BP981,5,0),"") -> 26 | Y12: =IFERROR(VLOOKUP(M12,'Daily Attendance 25-26'!$A$1:BP981,5,0),"") -> 28 | Z12: =IFERROR(VLOOKUP(N12,'Daily Attendance 25-26'!$A$1:BP981,5,0),"") | AA12: =SUM(D12:Z12) -> 184
A13: PR 04 | B13: =IFERROR(VLOOKUP(A13,'Employees List'!$B$2:E981,4,0),"") -> RUPESH KISAN | C13: =$O$1&B13 -> AprilRUPESH KISAN | D13: =$P$1&B13 -> MayRUPESH KISAN | E13: =$Q$1&B13 -> JuneRUPESH KISAN | F13: =$R$1&B13 -> JulyRUPESH KISAN | G13: =$S$1&B13 -> AugustRUPESH KISAN | H13: =$T$1&B13 -> SeptemberRUPESH KISAN | I13: =$U$1&B13 -> OctoberRUPESH KISAN | J13: =$V$1&B13 -> NovemberRUPESH KISAN | K13: =$W$1&B13 -> DecemberRUPESH KISAN | L13: =$X$1&B13 -> JanuaryRUPESH KISAN | M13: =$Y$1&B13 -> FebruaryRUPESH KISAN | N13: =$Z$1&B13 -> MarchRUPESH KISAN | O13: =IFERROR(VLOOKUP(C13,'Daily Attendance 25-26'!$A$1:BP981,5,0),"") -> 10 | P13: =IFERROR(VLOOKUP(D13,'Daily Attendance 25-26'!$A$1:BP981,5,0),"") -> 31 | Q13: =IFERROR(VLOOKUP(E13,'Daily Attendance 25-26'!$A$1:BP981,5,0),"") -> 29 | R13: =IFERROR(VLOOKUP(F13,'Daily Attendance 25-26'!$A$1:BP981,5,0),"") -> 31 | S13: =IFERROR(VLOOKUP(G13,'Daily Attendance 25-26'!$A$1:BP981,5,0),"") -> 30 | T13: =IFERROR(VLOOKUP(H13,'Daily Attendance 25-26'!$A$1:BP981,5,0),"") | U13: =IFERROR(VLOOKUP(I13,'Daily Attendance 25-26'!$A$1:BP981,5,0),"") | V13: =IFERROR(VLOOKUP(J13,'Daily Attendance 25-26'!$A$1:BP981,5,0),"") | W13: =IFERROR(VLOOKUP(K13,'Daily Attendance 25-26'!$A$1:BP981,5,0),"") | X13: =IFERROR(VLOOKUP(L13,'Daily Attendance 25-26'!$A$1:BP981,5,0),"") | Y13: =IFERROR(VLOOKUP(M13,'Daily Attendance 25-26'!$A$1:BP981,5,0),"") | Z13: =IFERROR(VLOOKUP(N13,'Daily Attendance 25-26'!$A$1:BP981,5,0),"") | AA13: =SUM(D13:Z13) -> 131
A14: PR 21 | B14: =IFERROR(VLOOKUP(A14,'Employees List'!$B$2:E981,4,0),"") -> LIPAN | C14: =$O$1&B14 -> AprilLIPAN | D14: =$P$1&B14 -> MayLIPAN | E14: =$Q$1&B14 -> JuneLIPAN | F14: =$R$1&B14 -> JulyLIPAN | G14: =$S$1&B14 -> AugustLIPAN | H14: =$T$1&B14 -> SeptemberLIPAN | I14: =$U$1&B14 -> OctoberLIPAN | J14: =$V$1&B14 -> NovemberLIPAN | K14: =$W$1&B14 -> DecemberLIPAN | L14: =$X$1&B14 -> JanuaryLIPAN | M14: =$Y$1&B14 -> FebruaryLIPAN | N14: =$Z$1&B14 -> MarchLIPAN | O14: =IFERROR(VLOOKUP(C14,'Daily Attendance 25-26'!$A$1:BP981,5,0),"") -> 10 | P14: =IFERROR(VLOOKUP(D14,'Daily Attendance 25-26'!$A$1:BP981,5,0),"") -> 30 | Q14: =IFERROR(VLOOKUP(E14,'Daily Attendance 25-26'!$A$1:BP981,5,0),"") -> 30 | R14: =IFERROR(VLOOKUP(F14,'Daily Attendance 25-26'!$A$1:BP981,5,0),"") -> 31 | S14: =IFERROR(VLOOKUP(G14,'Daily Attendance 25-26'!$A$1:BP981,5,0),"") -> 31 | T14: =IFERROR(VLOOKUP(H14,'Daily Attendance 25-26'!$A$1:BP981,5,0),"") | U14: =IFERROR(VLOOKUP(I14,'Daily Attendance 25-26'!$A$1:BP981,5,0),"") | V14: =IFERROR(VLOOKUP(J14,'Daily Attendance 25-26'!$A$1:BP981,5,0),"") | W14: =IFERROR(VLOOKUP(K14,'Daily Attendance 25-26'!$A$1:BP981,5,0),"") | X14: =IFERROR(VLOOKUP(L14,'Daily Attendance 25-26'!$A$1:BP981,5,0),"") | Y14: =IFERROR(VLOOKUP(M14,'Daily Attendance 25-26'!$A$1:BP981,5,0),"") | Z14: =IFERROR(VLOOKUP(N14,'Daily Attendance 25-26'!$A$1:BP981,5,0),"") | AA14: =SUM(D14:Z14) -> 132
A15: PR 24 | B15: =IFERROR(VLOOKUP(A15,'Employees List'!$B$2:E981,4,0),"") -> NILAMANI KISAN.B | C15: =$O$1&B15 -> AprilNILAMANI KISAN.B | D15: =$P$1&B15 -> MayNILAMANI KISAN.B | E15: =$Q$1&B15 -> JuneNILAMANI KISAN.B | F15: =$R$1&B15 -> JulyNILAMANI KISAN.B | G15: =$S$1&B15 -> AugustNILAMANI KISAN.B | H15: =$T$1&B15 -> SeptemberNILAMANI KISAN.B | I15: =$U$1&B15 -> OctoberNILAMANI KISAN.B | J15: =$V$1&B15 -> NovemberNILAMANI KISAN.B | K15: =$W$1&B15 -> DecemberNILAMANI KISAN.B | L15: =$X$1&B15 -> JanuaryNILAMANI KISAN.B | M15: =$Y$1&B15 -> FebruaryNILAMANI KISAN.B | N15: =$Z$1&B15 -> MarchNILAMANI KISAN.B | O15: =IFERROR(VLOOKUP(C15,'Daily Attendance 25-26'!$A$1:BP981,5,0),"") -> 27 | P15: =IFERROR(VLOOKUP(D15,'Daily Attendance 25-26'!$A$1:BP981,5,0),"") -> 29 | Q15: =IFERROR(VLOOKUP(E15,'Daily Attendance 25-26'!$A$1:BP981,5,0),"") -> 15 | R15: =IFERROR(VLOOKUP(F15,'Daily Attendance 25-26'!$A$1:BP981,5,0),"") | S15: =IFERROR(VLOOKUP(G15,'Daily Attendance 25-26'!$A$1:BP981,5,0),"") | T15: =IFERROR(VLOOKUP(H15,'Daily Attendance 25-26'!$A$1:BP981,5,0),"") | U15: =IFERROR(VLOOKUP(I15,'Daily Attendance 25-26'!$A$1:BP981,5,0),"") | V15: =IFERROR(VLOOKUP(J15,'Daily Attendance 25-26'!$A$1:BP981,5,0),"") | W15: =IFERROR(VLOOKUP(K15,'Daily Attendance 25-26'!$A$1:BP981,5,0),"") -> 27 | X15: =IFERROR(VLOOKUP(L15,'Daily Attendance 25-26'!$A$1:BP981,5,0),"") -> 10 | Y15: =IFERROR(VLOOKUP(M15,'Daily Attendance 25-26'!$A$1:BP981,5,0),"") -> 0 | Z15: =IFERROR(VLOOKUP(N15,'Daily Attendance 25-26'!$A$1:BP981,5,0),"") | AA15: =SUM(D15:Z15) -> 108
A16: PR 27 | B16: =IFERROR(VLOOKUP(A16,'Employees List'!$B$2:E981,4,0),"") -> PARSHU BAGH | C16: =$O$1&B16 -> AprilPARSHU BAGH | D16: =$P$1&B16 -> MayPARSHU BAGH | E16: =$Q$1&B16 -> JunePARSHU BAGH | F16: =$R$1&B16 -> JulyPARSHU BAGH | G16: =$S$1&B16 -> AugustPARSHU BAGH | H16: =$T$1&B16 -> SeptemberPARSHU BAGH | I16: =$U$1&B16 -> OctoberPARSHU BAGH | J16: =$V$1&B16 -> NovemberPARSHU BAGH | K16: =$W$1&B16 -> DecemberPARSHU BAGH | L16: =$X$1&B16 -> JanuaryPARSHU BAGH | M16: =$Y$1&B16 -> FebruaryPARSHU BAGH | N16: =$Z$1&B16 -> MarchPARSHU BAGH | O16: =IFERROR(VLOOKUP(C16,'Daily Attendance 25-26'!$A$1:BP981,5,0),"") -> 9 | P16: =IFERROR(VLOOKUP(D16,'Daily Attendance 25-26'!$A$1:BP981,5,0),"") | Q16: =IFERROR(VLOOKUP(E16,'Daily Attendance 25-26'!$A$1:BP981,5,0),"") | R16: =IFERROR(VLOOKUP(F16,'Daily Attendance 25-26'!$A$1:BP981,5,0),"") -> 24 | S16: =IFERROR(VLOOKUP(G16,'Daily Attendance 25-26'!$A$1:BP981,5,0),"") -> 4.5 | T16: =IFERROR(VLOOKUP(H16,'Daily Attendance 25-26'!$A$1:BP981,5,0),"") | U16: =IFERROR(VLOOKUP(I16,'Daily Attendance 25-26'!$A$1:BP981,5,0),"") | V16: =IFERROR(VLOOKUP(J16,'Daily Attendance 25-26'!$A$1:BP981,5,0),"") | W16: =IFERROR(VLOOKUP(K16,'Daily Attendance 25-26'!$A$1:BP981,5,0),"") | X16: =IFERROR(VLOOKUP(L16,'Daily Attendance 25-26'!$A$1:BP981,5,0),"") -> 26 | Y16: =IFERROR(VLOOKUP(M16,'Daily Attendance 25-26'!$A$1:BP981,5,0),"") -> 24 | Z16: =IFERROR(VLOOKUP(N16,'Daily Attendance 25-26'!$A$1:BP981,5,0),"") | AA16: =SUM(D16:Z16) -> 87.5
O17: =IFERROR(VLOOKUP(C17,'Daily Attendance 25-26'!$A$1:BP981,5,0),"")

Sheet Advance Sheet
A1: Date | B1: Name | C1: Emp id | D1: Month | E1: Advance Requested | F1: Advance Provided | G1: Advance Deducted | H1: Reason | I1: Status
A2: 45889 | B2: =IFERROR(VLOOKUP(C2,'Employees List'!$B$1:$G$999,4,0),"") -> GANESH | C2: PR 02 | D2: August | F2: 40500 | H2: Opening Balance | I2: Paid
A3: 45889 | B3: =IFERROR(VLOOKUP(C3,'Employees List'!$B$1:$G$999,4,0),"") -> REVATHI.S | C3: PR 08 | D3: August | F3: 2000 | G3: 1000 | H3: Opening Balance | I3: Paid
A4: 45889 | B4: =IFERROR(VLOOKUP(C4,'Employees List'!$B$1:$G$999,4,0),"") -> REVATHI.S | C4: PR 08 | D4: August | E4: 2000 | F4: 2000 | G4: 2000 | H4: Hospital Expenses | I4: Paid
A5: 45894 | B5: =IFERROR(VLOOKUP(C5,'Employees List'!$B$1:$G$999,4,0),"") -> LIPAN | C5: PR 21 | D5: August | E5: 5000 | F5: 5000 | G5: 5000 | H5: Bike EMI | I5: Paid
A6: 45897 | B6: =IFERROR(VLOOKUP(C6,'Employees List'!$B$1:$G$999,4,0),"") -> ADHIKARI BALIA.A | C6: PR 03 | D6: August | E6: 2000 | F6: 2000 | H6: Home | I6: Paid
A7: 45901 | B7: =IFERROR(VLOOKUP(C7,'Employees List'!$B$1:$G$999,4,0),"") -> ADHIKARI BALIA.A | C7: PR 03 | D7: September | E7: 5000 | F7: 5000 | G7: 7000 | H7: Grandma Passed | I7: Paid
A8: 45903 | B8: =IFERROR(VLOOKUP(C8,'Employees List'!$B$1:$G$999,4,0),"") -> RUPESH KISAN | C8: PR 04 | D8: September | E8: 10000 | F8: 7000 | G8: 7000 | H8: Loan EMI | I8: Paid
A9: 45904 | B9: =IFERROR(VLOOKUP(C9,'Employees List'!$B$1:$G$999,4,0),"") -> GANESH | C9: PR 02 | D9: September | E9: 500 | F9: 500 | G9: 5000 | H9: Gift purpose | I9: Paid
A10: 45917 | B10: =IFERROR(VLOOKUP(C10,'Employees List'!$B$1:$G$999,4,0),"") -> REVATHI.S | C10: PR 08 | D10: September | E10: 3000 | F10: 3000 | G10: 3000 | H10: Loan EMI | I10: Paid
A11: 45922 | B11: =IFERROR(VLOOKUP(C11,'Employees List'!$B$1:$G$999,4,0),"") -> SANJAY BAGARTTI.K | C11: PR 05 | D11: September | E11: 5000 | F11: 5000 | G11: 5000 | H11: EMI For Loan | I11: Paid
A12: 45929 | B12: =IFERROR(VLOOKUP(C12,'Employees List'!$B$1:$G$999,4,0),"") -> RUPESH KISAN | C12: PR 04 | D12: September | E12: 1000 | H12: Personal | I12: Not Paid
A13: 45929 | B13: =IFERROR(VLOOKUP(C13,'Employees List'!$B$1:$G$999,4,0),"") -> GANESH | C13: PR 02 | D13: September | E13: 500 | G13: 2000 | H13: Personal | I13: Not Paid
A14: 45940 | B14: =IFERROR(VLOOKUP(C14,'Employees List'!$B$1:$G$999,4,0),"") -> REVATHI.S | C14: PR 08
A15: 45953 | B15: =IFERROR(VLOOKUP(C15,'Employees List'!$B$1:$G$999,4,0),"") -> LIPAN | C15: PR 21 | D15: October | E15: 5000 | F15: 5000 | H15: Personal | I15: Paid
A16: 45965 | B16: =IFERROR(VLOOKUP(C16,'Employees List'!$B$1:$G$999,4,0),"") -> REVATHI.S | C16: PR 08 | D16: October | E16: 500 | F16: 500 | G16: 500 | H16: Hospital | I16: Paid
A17: 45980 | B17: =IFERROR(VLOOKUP(C17,'Employees List'!$B$1:$G$999,4,0),"") -> REVATHI.S | C17: PR 08 | D17: November | E17: 3000 | F17: 3000 | G17: 1500 | H17: Loan | I17: Paid
A18: 45990 | B18: =IFERROR(VLOOKUP(C18,'Employees List'!$B$1:$G$999,4,0),"") -> GANESH | C18: PR 02 | D18: November | E18: 800 | F18: 800 | G18: 1800 | H18: Personal | I18: Paid
A19: 45995 | B19: =IFERROR(VLOOKUP(C19,'Employees List'!$B$1:$G$999,4,0),"") -> NILAMANI KISAN.B | C19: PR 24 | D19: December | E19: 3000 | F19: 3000 | H19: SBI AC - Food | I19: Paid
A20: 46012 | B20: =IFERROR(VLOOKUP(C20,'Employees List'!$B$1:$G$999,4,0),"") -> SANJAY BAGARTTI.K | C20: PR 05 | D20: December | E20: 5000 | F20: 5000 | I20: Paid
A21: 46014 | B21: =IFERROR(VLOOKUP(C21,'Employees List'!$B$1:$G$999,4,0),"") -> REVATHI.S | C21: PR 08 | D21: December | E21: 500 | F21: 500 | I21: Paid
A22: 46053 | B22: =IFERROR(VLOOKUP(C22,'Employees List'!$B$1:$G$999,4,0),"") -> GANESH | C22: PR 02 | D22: December | E22: 500 | F22: 500 | G22: 2500 | H22: Personal | I22: Request Apply
B23: =IFERROR(VLOOKUP(C23,'Employees List'!$B$1:$G$999,4,0),"") -> NILAMANI KISAN.B | C23: PR 24 | D23: December | E23: 2000 | F23: 2000 | H23: FOOD | I23: Request Apply
B24: =IFERROR(VLOOKUP(C24,'Employees List'!$B$1:$G$999,4,0),"") -> ADHIKARI BALIA.A | C24: PR 03 | D24: January | E24: 2000 | F24: 2000 | G24: 2000 | I24: Paid
B25: =IFERROR(VLOOKUP(C25,'Employees List'!$B$1:$G$999,4,0),"") -> ADHIKARI BALIA.A | C25: PR 03 | D25: January | E25: 4000 | F25: 4000 | G25: 4000
B26: =IFERROR(VLOOKUP(C26,'Employees List'!$B$1:$G$999,4,0),"") -> PARSHU BAGH | C26: PR 27 | D26: January | E26: 2000 | F26: 2000 | G26: 2000 | I26: Paid
A27: 46032 | B27: =IFERROR(VLOOKUP(C27,'Employees List'!$B$1:$G$999,4,0),"") -> REVATHI.S | C27: PR 08 | D27: January | G27: 1000 | I27: Received
A28: 46056 | B28: =IFERROR(VLOOKUP(C28,'Employees List'!$B$1:$G$999,4,0),"") -> GANESH | C28: PR 02 | D28: February | E28: 200 | F28: 200 | G28: 10000
A29: 46074 | B29: =IFERROR(VLOOKUP(C29,'Employees List'!$B$1:$G$999,4,0),"") -> PARSHU BAGH | C29: PR 27 | D29: February | E29: 4000 | F29: 4000 | H29: Going To Native | I29: Paid
A30: 46083 | B30: =IFERROR(VLOOKUP(C30,'Employees List'!$B$1:$G$999,4,0),"") -> REVATHI.S | C30: PR 08 | D30: March | E30: 300 | F30: 300 | I30: Paid
A31: 46084 | B31: =IFERROR(VLOOKUP(C31,'Employees List'!$B$1:$G$999,4,0),"") -> ADHIKARI BALIA.A | C31: PR 03 | D31: March | E31: 2000 | H31: Food | I31: Paid
B32: =IFERROR(VLOOKUP(C32,'Employees List'!$B$1:$G$999,4,0),"")
B33: =IFERROR(VLOOKUP(C33,'Employees List'!$B$1:$G$999,4,0),"")
B34: =IFERROR(VLOOKUP(C34,'Employees List'!$B$1:$G$999,4,0),"")
B35: =IFERROR(VLOOKUP(C35,'Employees List'!$B$1:$G$999,4,0),"")
B36: =IFERROR(VLOOKUP(C36,'Employees List'!$B$1:$G$999,4,0),"")
B37: =IFERROR(VLOOKUP(C37,'Employees List'!$B$1:$G$999,4,0),"")
B38: =IFERROR(VLOOKUP(C38,'Employees List'!$B$1:$G$999,4,0),"")
B39: =IFERROR(VLOOKUP(C39,'Employees List'!$B$1:$G$999,4,0),"")
B40: =IFERROR(VLOOKUP(C40,'Employees List'!$B$1:$G$999,4,0),"")
...

Sheet Advance Report
A2: NAME | B2: GANESH | K2: =IF(B2="All","","and B = '"&B2&"'") -> and B = 'GANESH'
A3: MONTH | B3: All | K3: =IF(B3="All","","and C = '"&B3&"'")
A4: BALANCE | B4: =F1000-G1000 -> 21200 | K4: =CONCATENATE("select * where 1=1",K2,K3) -> select * where 1=1and B = 'GANESH'
A7: =IFERROR(__xludf.DUMMYFUNCTION("QUERY('Advance Sheet'!A1:I1000,K4)"),"Date") -> Date | B7: =IFERROR(__xludf.DUMMYFUNCTION("""COMPUTED_VALUE"""),"Name") -> Name | C7: =IFERROR(__xludf.DUMMYFUNCTION("""COMPUTED_VALUE"""),"Emp id") -> Emp id | D7: =IFERROR(__xludf.DUMMYFUNCTION("""COMPUTED_VALUE"""),"Month") -> Month | E7: =IFERROR(__xludf.DUMMYFUNCTION("""COMPUTED_VALUE"""),"Advance Requested") -> Advance Requested | F7: =IFERROR(__xludf.DUMMYFUNCTION("""COMPUTED_VALUE"""),"Advance Provided") -> Advance Provided | G7: =IFERROR(__xludf.DUMMYFUNCTION("""COMPUTED_VALUE"""),"Advance Deducted") -> Advance Deducted | H7: =IFERROR(__xludf.DUMMYFUNCTION("""COMPUTED_VALUE"""),"Reason") -> Reason | I7: =IFERROR(__xludf.DUMMYFUNCTION("""COMPUTED_VALUE"""),"Status") -> Status
A8: =IFERROR(__xludf.DUMMYFUNCTION("""COMPUTED_VALUE"""),45889.0) -> 45889 | B8: =IFERROR(__xludf.DUMMYFUNCTION("""COMPUTED_VALUE"""),"GANESH") -> GANESH | C8: =IFERROR(__xludf.DUMMYFUNCTION("""COMPUTED_VALUE"""),"PR 02") -> PR 02 | D8: =IFERROR(__xludf.DUMMYFUNCTION("""COMPUTED_VALUE"""),"August") -> August | F8: =IFERROR(__xludf.DUMMYFUNCTION("""COMPUTED_VALUE"""),40500.0) -> 40500 | H8: =IFERROR(__xludf.DUMMYFUNCTION("""COMPUTED_VALUE"""),"Opening Balance") -> Opening Balance | I8: =IFERROR(__xludf.DUMMYFUNCTION("""COMPUTED_VALUE"""),"Paid") -> Paid
A9: =IFERROR(__xludf.DUMMYFUNCTION("""COMPUTED_VALUE"""),45904.0) -> 45904 | B9: =IFERROR(__xludf.DUMMYFUNCTION("""COMPUTED_VALUE"""),"GANESH") -> GANESH | C9: =IFERROR(__xludf.DUMMYFUNCTION("""COMPUTED_VALUE"""),"PR 02") -> PR 02 | D9: =IFERROR(__xludf.DUMMYFUNCTION("""COMPUTED_VALUE"""),"September") -> September | E9: =IFERROR(__xludf.DUMMYFUNCTION("""COMPUTED_VALUE"""),500.0) -> 500 | F9: =IFERROR(__xludf.DUMMYFUNCTION("""COMPUTED_VALUE"""),500.0) -> 500 | G9: =IFERROR(__xludf.DUMMYFUNCTION("""COMPUTED_VALUE"""),5000.0) -> 5000 | H9: =IFERROR(__xludf.DUMMYFUNCTION("""COMPUTED_VALUE"""),"Gift purpose") -> Gift purpose | I9: =IFERROR(__xludf.DUMMYFUNCTION("""COMPUTED_VALUE"""),"Paid") -> Paid
A10: =IFERROR(__xludf.DUMMYFUNCTION("""COMPUTED_VALUE"""),45929.0) -> 45929 | B10: =IFERROR(__xludf.DUMMYFUNCTION("""COMPUTED_VALUE"""),"GANESH") -> GANESH | C10: =IFERROR(__xludf.DUMMYFUNCTION("""COMPUTED_VALUE"""),"PR 02") -> PR 02 | D10: =IFERROR(__xludf.DUMMYFUNCTION("""COMPUTED_VALUE"""),"September") -> September | E10: =IFERROR(__xludf.DUMMYFUNCTION("""COMPUTED_VALUE"""),500.0) -> 500 | G10: =IFERROR(__xludf.DUMMYFUNCTION("""COMPUTED_VALUE"""),2000.0) -> 2000 | H10: =IFERROR(__xludf.DUMMYFUNCTION("""COMPUTED_VALUE"""),"Personal") -> Personal | I10: =IFERROR(__xludf.DUMMYFUNCTION("""COMPUTED_VALUE"""),"Not Paid") -> Not Paid
A11: =IFERROR(__xludf.DUMMYFUNCTION("""COMPUTED_VALUE"""),45990.0) -> 45990 | B11: =IFERROR(__xludf.DUMMYFUNCTION("""COMPUTED_VALUE"""),"GANESH") -> GANESH | C11: =IFERROR(__xludf.DUMMYFUNCTION("""COMPUTED_VALUE"""),"PR 02") -> PR 02 | D11: =IFERROR(__xludf.DUMMYFUNCTION("""COMPUTED_VALUE"""),"November") -> November | E11: =IFERROR(__xludf.DUMMYFUNCTION("""COMPUTED_VALUE"""),800.0) -> 800 | F11: =IFERROR(__xludf.DUMMYFUNCTION("""COMPUTED_VALUE"""),800.0) -> 800 | G11: =IFERROR(__xludf.DUMMYFUNCTION("""COMPUTED_VALUE"""),1800.0) -> 1800 | H11: =IFERROR(__xludf.DUMMYFUNCTION("""COMPUTED_VALUE"""),"Personal") -> Personal | I11: =IFERROR(__xludf.DUMMYFUNCTION("""COMPUTED_VALUE"""),"Paid") -> Paid
A12: =IFERROR(__xludf.DUMMYFUNCTION("""COMPUTED_VALUE"""),46053.0) -> 46053 | B12: =IFERROR(__xludf.DUMMYFUNCTION("""COMPUTED_VALUE"""),"GANESH") -> GANESH | C12: =IFERROR(__xludf.DUMMYFUNCTION("""COMPUTED_VALUE"""),"PR 02") -> PR 02 | D12: =IFERROR(__xludf.DUMMYFUNCTION("""COMPUTED_VALUE"""),"December") -> December | E12: =IFERROR(__xludf.DUMMYFUNCTION("""COMPUTED_VALUE"""),500.0) -> 500 | F12: =IFERROR(__xludf.DUMMYFUNCTION("""COMPUTED_VALUE"""),500.0) -> 500 | G12: =IFERROR(__xludf.DUMMYFUNCTION("""COMPUTED_VALUE"""),2500.0) -> 2500 | H12: =IFERROR(__xludf.DUMMYFUNCTION("""COMPUTED_VALUE"""),"Personal") -> Personal | I12: =IFERROR(__xludf.DUMMYFUNCTION("""COMPUTED_VALUE"""),"Request Apply") -> Request Apply
A13: =IFERROR(__xludf.DUMMYFUNCTION("""COMPUTED_VALUE"""),46056.0) -> 46056 | B13: =IFERROR(__xludf.DUMMYFUNCTION("""COMPUTED_VALUE"""),"GANESH") -> GANESH | C13: =IFERROR(__xludf.DUMMYFUNCTION("""COMPUTED_VALUE"""),"PR 02") -> PR 02 | D13: =IFERROR(__xludf.DUMMYFUNCTION("""COMPUTED_VALUE"""),"February") -> February | E13: =IFERROR(__xludf.DUMMYFUNCTION("""COMPUTED_VALUE"""),200.0) -> 200 | F13: =IFERROR(__xludf.DUMMYFUNCTION("""COMPUTED_VALUE"""),200.0) -> 200 | G13: =IFERROR(__xludf.DUMMYFUNCTION("""COMPUTED_VALUE"""),10000.0) -> 10000
F1000: =SUM(F8:F999) -> 42500 | G1000: =SUM(G8:G999) -> 21300

Sheet Salary Calculation
A1: Salary Slip No | B1: Month | C1: Employee Code | D1: No of Days Name | E1: No of OT Name | F1: Name | G1: SALARY | H1: Account Number | I1: Total Wages 25-26 | J1: Basic Pay | K1: HRA | L1: No Of Days In a Month | M1: No Of Days Present | N1: OT Hours | O1: Bonus | P1: Advance | Q1: Gross Wages | R1: OT Amount | S1: Netpay | T1: ESI | U1: Total Salary
A2: CPIEMP001 | B2: April | C2: AC 01 | D2: =B2&F2 -> AprilBHUVANESHWARAN.V | E2: =D2&$N$1 -> AprilBHUVANESHWARAN.VOT Hours | F2: =IFERROR(VLOOKUP(C2,'Employees List'!$B$1:$I$999,4,0),"") -> BHUVANESHWARAN.V | G2: =S2 -> 66900 | H2: =IFERROR(VLOOKUP(C2,'Employees List'!$B$2:$I$991,7,0),"") -> 500101011548924 | I2: =IFERROR(VLOOKUP(F2,'Employees List'!$E$1:$AE$991,6,0),"") -> 66000 | J2: =I2*70% -> 46200 | K2: =I2*30% -> 19800 | L2: =IFERROR(VLOOKUP(B2,'Employees List'!$A$2:$K$991,11,0),"") -> 30 | M2: =IFERROR(VLOOKUP(D2,'Daily Attendance 25-26'!$A$4:BP999,5,0),"") -> 30 | N2: =IFERROR(VLOOKUP(E2,'Daily Attendance 25-26'!$A$1:$BO$1741,5,0),"") -> 0 | O2: 900 | Q2: =I2/L2*M2 -> 66000 | R2: =I2/L2/8*1.5*N2 -> 0 | S2: =Q2+R2-P2+O2 -> 66900 | T2: 0 | U2: =Q2+R2+O2 -> 66900
